Workbook

Sheet Initial Projections - 2025
A1: 0 | F1: Major League - PDC | R1: Minor League - PDC | AD1: Single A Jays | AJ1: SSM | AL1: Other | AX1: TOTALS
A2: Day | B2: Date | C2: Period | D2: Week | E2: Camp Name | F2: Breakfast | G2: 22.25 | H2: Lunch | I2: 22.25 | J2: Dinner | K2: 22.25 | L2: Umpire | M2: 22.25 | N2: Post Game Meal | O2: 22.25 | P2: Snack | Q2: 1.64 | R2: Breakfast | S2: 11.12 | T2: Lunch | U2: 11.12 | V2: Dinner | W2: 11.12 | X2: Blank | Y2: 0 | Z2: Blank | AA2: 0 | AB2: Blank | AC2: 0 | AD2: Breakfast | AE2: 15.89 | AF2: PRE-GAME | AG2: 15.89 | AH2: POST-GAME | AI2: 15.89 | AJ2: Stadium Staff Meals | AK2: 15.89 | AL2: Fun $$$$ Allocated | AM2: 27404 | AN2: Media Meals | AO2: 15 | AP2: MLB G&G - Pantry | AQ2: 1.64 | AR2: MiLB G&G - Pantry | AS2: 1.64 | AT2: MLB - Catering | AU2: 34 | AV2: Team Canada | AW2: 11.12 | AX2: Total Revenue | AY2: Total Meals | AZ2: Total Snacks | BA2: Total Charged Items | BB2: Average $/Item
A3: Mon | B3: 45656 | C3: 1 | D3: Week 1 | F3: 0 | H3: 0 | J3: 0 | L3: 0 | N3: 0 | P3: 0 | R3: 0 | T3: 0 | V3: 0 | X3: 0 | Z3: 0 | AB3: 0 | AD3: 0 | AF3: 0 | AH3: 0 | AL3: 0 | AX3: =(F3*G$2)+(H3*I$2)+(J3*K$2)+(L3*M$2)+(N3*O$2)+(P3*Q$2)+(R3*S$2)+(T3*U$2)+(V3*W$2)+(X3*Y$2)+(Z3*AA$2)+(AB3*AC$2)+(AN3*AO$2)+(AP3*AQ$2)+(AR3*AS$2)+(AT3*AU$2)+(AV3*AW$2)+(AD3*AE$2)+(AF3*AG$2)+(AH3*AI$2)+(AJ3*$AK$2) -> 0 | AY3: =sum(F3:AK3) + sum(AN3:AW3) -> 0 | AZ3: 0 | BA3: =sum(AY3:AZ3) -> 0 | BB3: =iferror(AX3/BA3,"")
A4: Tue | B4: =B3+1 -> 45657 | C4: 1 | D4: Week 1 | F4: 0 | H4: 0 | J4: 0 | L4: 0 | N4: 0 | P4: 0 | R4: 0 | T4: 0 | V4: 0 | X4: 0 | Z4: 0 | AB4: 0 | AD4: 0 | AF4: 0 | AH4: 0 | AL4: 0 | AX4: =(F4*G$2)+(H4*I$2)+(J4*K$2)+(L4*M$2)+(N4*O$2)+(P4*Q$2)+(R4*S$2)+(T4*U$2)+(V4*W$2)+(X4*Y$2)+(Z4*AA$2)+(AB4*AC$2)+(AN4*AO$2)+(AP4*AQ$2)+(AR4*AS$2)+(AT4*AU$2)+(AV4*AW$2)+(AD4*AE$2)+(AF4*AG$2)+(AH4*AI$2)+(AJ4*$AK$2) -> 0 | AY4: =sum(F4:AK4) + sum(AN4:AW4) -> 0 | AZ4: 0 | BA4: =sum(AY4:AZ4) -> 0 | BB4: =iferror(AX4/BA4,"")
A5: Wed | B5: =B4+1 -> 45658 | C5: 1 | D5: Week 1 | F5: 0 | H5: 0 | J5: 0 | L5: 0 | N5: 0 | P5: 0 | R5: 0 | T5: 0 | V5: 0 | X5: 0 | Z5: 0 | AB5: 0 | AD5: 0 | AF5: 0 | AH5: 0 | AL5: 0 | AX5: =(F5*G$2)+(H5*I$2)+(J5*K$2)+(L5*M$2)+(N5*O$2)+(P5*Q$2)+(R5*S$2)+(T5*U$2)+(V5*W$2)+(X5*Y$2)+(Z5*AA$2)+(AB5*AC$2)+(AN5*AO$2)+(AP5*AQ$2)+(AR5*AS$2)+(AT5*AU$2)+(AV5*AW$2)+(AD5*AE$2)+(AF5*AG$2)+(AH5*AI$2)+(AJ5*$AK$2) -> 0 | AY5: =sum(F5:AK5) + sum(AN5:AW5) -> 0 | AZ5: 0 | BA5: =sum(AY5:AZ5) -> 0 | BB5: =iferror(AX5/BA5,"")
A6: Thurs | B6: =B5+1 -> 45659 | C6: 1 | D6: Week 1 | F6: 0 | H6: 0 | J6: 0 | L6: 0 | N6: 0 | P6: 0 | R6: 0 | T6: 0 | V6: 0 | X6: 0 | Z6: 0 | AB6: 0 | AD6: 0 | AF6: 0 | AH6: 0 | AL6: 0 | AX6: =(F6*G$2)+(H6*I$2)+(J6*K$2)+(L6*M$2)+(N6*O$2)+(P6*Q$2)+(R6*S$2)+(T6*U$2)+(V6*W$2)+(X6*Y$2)+(Z6*AA$2)+(AB6*AC$2)+(AN6*AO$2)+(AP6*AQ$2)+(AR6*AS$2)+(AT6*AU$2)+(AV6*AW$2)+(AD6*AE$2)+(AF6*AG$2)+(AH6*AI$2)+(AJ6*$AK$2) -> 0 | AY6: =sum(F6:AK6) + sum(AN6:AW6) -> 0 | AZ6: 0 | BA6: =sum(AY6:AZ6) -> 0 | BB6: =iferror(AX6/BA6,"")
A7: Fri | B7: =B6+1 -> 45660 | C7: 1 | D7: Week 1 | F7: 0 | H7: 0 | J7: 0 | L7: 0 | N7: 0 | P7: 0 | R7: 0 | T7: 0 | V7: 0 | X7: 0 | Z7: 0 | AB7: 0 | AD7: 0 | AF7: 0 | AH7: 0 | AL7: 0 | AX7: =(F7*G$2)+(H7*I$2)+(J7*K$2)+(L7*M$2)+(N7*O$2)+(P7*Q$2)+(R7*S$2)+(T7*U$2)+(V7*W$2)+(X7*Y$2)+(Z7*AA$2)+(AB7*AC$2)+(AN7*AO$2)+(AP7*AQ$2)+(AR7*AS$2)+(AT7*AU$2)+(AV7*AW$2)+(AD7*AE$2)+(AF7*AG$2)+(AH7*AI$2)+(AJ7*$AK$2) -> 0 | AY7: =sum(F7:AK7) + sum(AN7:AW7) -> 0 | AZ7: 0 | BA7: =sum(AY7:AZ7) -> 0 | BB7: =iferror(AX7/BA7,"")
A8: Sat | B8: =B7+1 -> 45661 | C8: 1 | D8: Week 1 | F8: 0 | H8: 0 | J8: 0 | L8: 0 | N8: 0 | P8: 0 | R8: 0 | T8: 0 | V8: 0 | X8: 0 | Z8: 0 | AB8: 0 | AD8: 0 | AF8: 0 | AH8: 0 | AL8: 0 | AX8: =(F8*G$2)+(H8*I$2)+(J8*K$2)+(L8*M$2)+(N8*O$2)+(P8*Q$2)+(R8*S$2)+(T8*U$2)+(V8*W$2)+(X8*Y$2)+(Z8*AA$2)+(AB8*AC$2)+(AN8*AO$2)+(AP8*AQ$2)+(AR8*AS$2)+(AT8*AU$2)+(AV8*AW$2)+(AD8*AE$2)+(AF8*AG$2)+(AH8*AI$2)+(AJ8*$AK$2) -> 0 | AY8: =sum(F8:AK8) + sum(AN8:AW8) -> 0 | AZ8: 0 | BA8: =sum(AY8:AZ8) -> 0 | BB8: =iferror(AX8/BA8,"")
A9: Sun | B9: =B8+1 -> 45662 | C9: 1 | D9: Week 1 | F9: 0 | H9: 0 | J9: 0 | L9: 0 | N9: 0 | P9: 0 | R9: 0 | T9: 0 | V9: 0 | X9: 0 | Z9: 0 | AB9: 0 | AD9: 0 | AF9: 0 | AH9: 0 | AL9: 0 | AX9: =(F9*G$2)+(H9*I$2)+(J9*K$2)+(L9*M$2)+(N9*O$2)+(P9*Q$2)+(R9*S$2)+(T9*U$2)+(V9*W$2)+(X9*Y$2)+(Z9*AA$2)+(AB9*AC$2)+(AN9*AO$2)+(AP9*AQ$2)+(AR9*AS$2)+(AT9*AU$2)+(AV9*AW$2)+(AD9*AE$2)+(AF9*AG$2)+(AH9*AI$2)+(AJ9*$AK$2) -> 0 | AY9: =sum(F9:AK9) + sum(AN9:AW9) -> 0 | AZ9: 0 | BA9: =sum(AY9:AZ9) -> 0 | BB9: =iferror(AX9/BA9,"")
A10: Mon | B10: =B9+1 -> 45663 | C10: 1 | D10: Week 2 | F10: 0 | H10: 0 | J10: 0 | L10: 0 | N10: 0 | P10: 0 | R10: 50 | T10: 50 | V10: 0 | X10: 0 | Z10: 0 | AB10: 0 | AD10: 0 | AF10: 0 | AH10: 0 | AL10: 0 | AX10: =(F10*G$2)+(H10*I$2)+(J10*K$2)+(L10*M$2)+(N10*O$2)+(P10*Q$2)+(R10*S$2)+(T10*U$2)+(V10*W$2)+(X10*Y$2)+(Z10*AA$2)+(AB10*AC$2)+(AN10*AO$2)+(AP10*AQ$2)+(AR10*AS$2)+(AT10*AU$2)+(AV10*AW$2)+(AD10*AE$2)+(AF10*AG$2)+(AH10*AI$2)+(AJ10*$AK$2) -> 1112 | AY10: =sum(F10:AK10) + sum(AN10:AW10) -> 100 | AZ10: 0 | BA10: =sum(AY10:AZ10) -> 100 | BB10: =iferror(AX10/BA10,"") -> 11.12
A11: Tue | B11: =B10+1 -> 45664 | C11: 1 | D11: Week 2 | F11: 0 | H11: 0 | J11: 0 | L11: 0 | N11: 0 | P11: 0 | R11: 60 | T11: 60 | V11: 0 | X11: 0 | Z11: 0 | AB11: 0 | AD11: 0 | AF11: 0 | AH11: 0 | AL11: 0 | AX11: =(F11*G$2)+(H11*I$2)+(J11*K$2)+(L11*M$2)+(N11*O$2)+(P11*Q$2)+(R11*S$2)+(T11*U$2)+(V11*W$2)+(X11*Y$2)+(Z11*AA$2)+(AB11*AC$2)+(AN11*AO$2)+(AP11*AQ$2)+(AR11*AS$2)+(AT11*AU$2)+(AV11*AW$2)+(AD11*AE$2)+(AF11*AG$2)+(AH11*AI$2)+(AJ11*$AK$2) -> 1334.4 | AY11: =sum(F11:AK11) + sum(AN11:AW11) -> 120 | AZ11: 0 | BA11: =sum(AY11:AZ11) -> 120 | BB11: =iferror(AX11/BA11,"") -> 11.12
A12: Wed | B12: =B11+1 -> 45665 | C12: 1 | D12: Week 2 | F12: 0 | H12: 0 | J12: 0 | L12: 0 | N12: 0 | P12: 0 | R12: 80 | T12: 80 | V12: 0 | X12: 0 | Z12: 0 | AB12: 0 | AD12: 0 | AF12: 0 | AH12: 0 | AL12: 0 | AX12: =(F12*G$2)+(H12*I$2)+(J12*K$2)+(L12*M$2)+(N12*O$2)+(P12*Q$2)+(R12*S$2)+(T12*U$2)+(V12*W$2)+(X12*Y$2)+(Z12*AA$2)+(AB12*AC$2)+(AN12*AO$2)+(AP12*AQ$2)+(AR12*AS$2)+(AT12*AU$2)+(AV12*AW$2)+(AD12*AE$2)+(AF12*AG$2)+(AH12*AI$2)+(AJ12*$AK$2) -> 1779.2 | AY12: =sum(F12:AK12) + sum(AN12:AW12) -> 160 | AZ12: 0 | BA12: =sum(AY12:AZ12) -> 160 | BB12: =iferror(AX12/BA12,"") -> 11.12
A13: Thurs | B13: =B12+1 -> 45666 | C13: 1 | D13: Week 2 | F13: 0 | H13: 0 | J13: 0 | L13: 0 | N13: 0 | P13: 0 | R13: 80 | T13: 80 | V13: 0 | X13: 0 | Z13: 0 | AB13: 0 | AD13: 0 | AF13: 0 | AH13: 0 | AL13: 0 | AX13: =(F13*G$2)+(H13*I$2)+(J13*K$2)+(L13*M$2)+(N13*O$2)+(P13*Q$2)+(R13*S$2)+(T13*U$2)+(V13*W$2)+(X13*Y$2)+(Z13*AA$2)+(AB13*AC$2)+(AN13*AO$2)+(AP13*AQ$2)+(AR13*AS$2)+(AT13*AU$2)+(AV13*AW$2)+(AD13*AE$2)+(AF13*AG$2)+(AH13*AI$2)+(AJ13*$AK$2) -> 1779.2 | AY13: =sum(F13:AK13) + sum(AN13:AW13) -> 160 | AZ13: 0 | BA13: =sum(AY13:AZ13) -> 160 | BB13: =iferror(AX13/BA13,"") -> 11.12
A14: Fri | B14: =B13+1 -> 45667 | C14: 1 | D14: Week 2 | F14: 0 | H14: 0 | J14: 0 | L14: 0 | N14: 0 | P14: 0 | R14: 65 | T14: 65 | V14: 0 | X14: 0 | Z14: 0 | AB14: 0 | AD14: 0 | AF14: 0 | AH14: 0 | AL14: 0 | AX14: =(F14*G$2)+(H14*I$2)+(J14*K$2)+(L14*M$2)+(N14*O$2)+(P14*Q$2)+(R14*S$2)+(T14*U$2)+(V14*W$2)+(X14*Y$2)+(Z14*AA$2)+(AB14*AC$2)+(AN14*AO$2)+(AP14*AQ$2)+(AR14*AS$2)+(AT14*AU$2)+(AV14*AW$2)+(AD14*AE$2)+(AF14*AG$2)+(AH14*AI$2)+(AJ14*$AK$2) -> 1445.6 | AY14: =sum(F14:AK14) + sum(AN14:AW14) -> 130 | AZ14: 0 | BA14: =sum(AY14:AZ14) -> 130 | BB14: =iferror(AX14/BA14,"") -> 11.12
A15: Sat | B15: =B14+1 -> 45668 | C15: 1 | D15: Week 2 | F15: 0 | H15: 0 | J15: 0 | L15: 0 | N15: 0 | P15: 0 | R15: 0 | T15: 0 | V15: 0 | X15: 0 | Z15: 0 | AB15: 0 | AD15: 0 | AF15: 0 | AH15: 0 | AL15: 0 | AX15: =(F15*G$2)+(H15*I$2)+(J15*K$2)+(L15*M$2)+(N15*O$2)+(P15*Q$2)+(R15*S$2)+(T15*U$2)+(V15*W$2)+(X15*Y$2)+(Z15*AA$2)+(AB15*AC$2)+(AN15*AO$2)+(AP15*AQ$2)+(AR15*AS$2)+(AT15*AU$2)+(AV15*AW$2)+(AD15*AE$2)+(AF15*AG$2)+(AH15*AI$2)+(AJ15*$AK$2) -> 0 | AY15: =sum(F15:AK15) + sum(AN15:AW15) -> 0 | AZ15: 0 | BA15: =sum(AY15:AZ15) -> 0 | BB15: =iferror(AX15/BA15,"")
... A30: Sun | B30: =B29+1 -> 45683 | C30: 1 | D30: Week 4 | F30: 0 | H30: 0 | J30: 0 | L30: 0 | N30: 0 | P30: 0 | R30: 0 | T30: 0 | V30: 0 | X30: 0 | Z30: 0 | AB30: 0 | AD30: 0 | AF30: 0 | AH30: 0 | AL30: 0 | AX30: =(F30*G$2)+(H30*I$2)+(J30*K$2)+(L30*M$2)+(N30*O$2)+(P30*Q$2)+(R30*S$2)+(T30*U$2)+(V30*W$2)+(X30*Y$2)+(Z30*AA$2)+(AB30*AC$2)+(AN30*AO$2)+(AP30*AQ$2)+(AR30*AS$2)+(AT30*AU$2)+(AV30*AW$2)+(AD30*AE$2)+(AF30*AG$2)+(AH30*AI$2)+(AJ30*$AK$2) -> 0 | AY30: =sum(F30:AK30) + sum(AN30:AW30) -> 0 | AZ30: 0 | BA30: =sum(AY30:AZ30) -> 0 | BB30: =iferror(AX30/BA30,"")
A31: Mon | B31: =B30+1 -> 45684 | C31: 2 | D31: Week 1 | E31: Early Camp | F31: 30 | H31: 30 | J31: 0 | L31: 0 | N31: 0 | P31: 0 | R31: 90 | T31: 90 | V31: 0 | X31: 0 | Z31: 0 | AB31: 0 | AD31: 0 | AF31: 0 | AH31: 0 | AL31: 0 | AX31: =(F31*G$2)+(H31*I$2)+(J31*K$2)+(L31*M$2)+(N31*O$2)+(P31*Q$2)+(R31*S$2)+(T31*U$2)+(V31*W$2)+(X31*Y$2)+(Z31*AA$2)+(AB31*AC$2)+(AN31*AO$2)+(AP31*AQ$2)+(AR31*AS$2)+(AT31*AU$2)+(AV31*AW$2)+(AD31*AE$2)+(AF31*AG$2)+(AH31*AI$2)+(AJ31*$AK$2) -> 3336.6 | AY31: =sum(F31:AK31) + sum(AN31:AW31) -> 240 | AZ31: 0 | BA31: =sum(AY31:AZ31) -> 240 | BB31: =iferror(AX31/BA31,"") -> 13.9025
A32: Tue | B32: =B31+1 -> 45685 | C32: 2 | D32: Week 1 | F32: 30 | H32: 30 | J32: 0 | L32: 0 | N32: 0 | P32: 0 | R32: 90 | T32: 90 | V32: 0 | X32: 0 | Z32: 0 | AB32: 0 | AD32: 0 | AF32: 0 | AH32: 0 | AL32: 0 | AX32: =(F32*G$2)+(H32*I$2)+(J32*K$2)+(L32*M$2)+(N32*O$2)+(P32*Q$2)+(R32*S$2)+(T32*U$2)+(V32*W$2)+(X32*Y$2)+(Z32*AA$2)+(AB32*AC$2)+(AN32*AO$2)+(AP32*AQ$2)+(AR32*AS$2)+(AT32*AU$2)+(AV32*AW$2)+(AD32*AE$2)+(AF32*AG$2)+(AH32*AI$2)+(AJ32*$AK$2) -> 3336.6 | AY32: =sum(F32:AK32) + sum(AN32:AW32) -> 240 | AZ32: 0 | BA32: =sum(AY32:AZ32) -> 240 | BB32: =iferror(AX32/BA32,"") -> 13.9025
A33: Wed | B33: =B32+1 -> 45686 | C33: 2 | D33: Week 1 | F33: 30 | H33: 30 | J33: 0 | L33: 0 | N33: 0 | P33: 0 | R33: 90 | T33: 90 | V33: 0 | X33: 0 | Z33: 0 | AB33: 0 | AD33: 0 | AF33: 0 | AH33: 0 | AL33: 0 | AX33: =(F33*G$2)+(H33*I$2)+(J33*K$2)+(L33*M$2)+(N33*O$2)+(P33*Q$2)+(R33*S$2)+(T33*U$2)+(V33*W$2)+(X33*Y$2)+(Z33*AA$2)+(AB33*AC$2)+(AN33*AO$2)+(AP33*AQ$2)+(AR33*AS$2)+(AT33*AU$2)+(AV33*AW$2)+(AD33*AE$2)+(AF33*AG$2)+(AH33*AI$2)+(AJ33*$AK$2) -> 3336.6 | AY33: =sum(F33:AK33) + sum(AN33:AW33) -> 240 | AZ33: 0 | BA33: =sum(AY33:AZ33) -> 240 | BB33: =iferror(AX33/BA33,"") -> 13.9025
A34: Thurs | B34: =B33+1 -> 45687 | C34: 2 | D34: Week 1 | F34: 30 | H34: 30 | J34: 0 | L34: 0 | N34: 0 | P34: 0 | R34: 90 | T34: 90 | V34: 0 | X34: 0 | Z34: 0 | AB34: 0 | AD34: 0 | AF34: 0 | AH34: 0 | AL34: 0 | AX34: =(F34*G$2)+(H34*I$2)+(J34*K$2)+(L34*M$2)+(N34*O$2)+(P34*Q$2)+(R34*S$2)+(T34*U$2)+(V34*W$2)+(X34*Y$2)+(Z34*AA$2)+(AB34*AC$2)+(AN34*AO$2)+(AP34*AQ$2)+(AR34*AS$2)+(AT34*AU$2)+(AV34*AW$2)+(AD34*AE$2)+(AF34*AG$2)+(AH34*AI$2)+(AJ34*$AK$2) -> 3336.6 | AY34: =sum(F34:AK34) + sum(AN34:AW34) -> 240 | AZ34: 0 | BA34: =sum(AY34:AZ34) -> 240 | BB34: =iferror(AX34/BA34,"") -> 13.9025
A35: Fri | B35: =B34+1 -> 45688 | C35: 2 | D35: Week 1 | F35: 30 | H35: 30 | J35: 0 | L35: 0 | N35: 0 | P35: 0 | R35: 90 | T35: 90 | V35: 0 | X35: 0 | Z35: 0 | AB35: 0 | AD35: 0 | AF35: 0 | AH35: 0 | AL35: 0 | AX35: =(F35*G$2)+(H35*I$2)+(J35*K$2)+(L35*M$2)+(N35*O$2)+(P35*Q$2)+(R35*S$2)+(T35*U$2)+(V35*W$2)+(X35*Y$2)+(Z35*AA$2)+(AB35*AC$2)+(AN35*AO$2)+(AP35*AQ$2)+(AR35*AS$2)+(AT35*AU$2)+(AV35*AW$2)+(AD35*AE$2)+(AF35*AG$2)+(AH35*AI$2)+(AJ35*$AK$2) -> 3336.6 | AY35: =sum(F35:AK35) + sum(AN35:AW35) -> 240 | AZ35: 0 | BA35: =sum(AY35:AZ35) -> 240 | BB35: =iferror(AX35/BA35,"") -> 13.9025
A36: Sat | B36: =B35+1 -> 45689 | C36: 2 | D36: Week 1 | F36: 0 | H36: 0 | J36: 0 | L36: 0 | N36: 0 | P36: 0 | R36: 0 | T36: 0 | V36: 0 | X36: 0 | Z36: 0 | AB36: 0 | AD36: 0 | AF36: 0 | AH36: 0 | AL36: 0 | AX36: =(F36*G$2)+(H36*I$2)+(J36*K$2)+(L36*M$2)+(N36*O$2)+(P36*Q$2)+(R36*S$2)+(T36*U$2)+(V36*W$2)+(X36*Y$2)+(Z36*AA$2)+(AB36*AC$2)+(AN36*AO$2)+(AP36*AQ$2)+(AR36*AS$2)+(AT36*AU$2)+(AV36*AW$2)+(AD36*AE$2)+(AF36*AG$2)+(AH36*AI$2)+(AJ36*$AK$2) -> 0 | AY36: =sum(F36:AK36) + sum(AN36:AW36) -> 0 | AZ36: 0 | BA36: =sum(AY36:AZ36) -> 0 | BB36: =iferror(AX36/BA36,"")
A37: Sun | B37: =B36+1 -> 45690 | C37: 2 | D37: Week 1 | F37: 0 | H37: 0 | J37: 0 | L37: 0 | N37: 0 | P37: 0 | R37: 0 | T37: 0 | V37: 0 | X37: 0 | Z37: 0 | AB37: 0 | AD37: 0 | AF37: 0 | AH37: 0 | AL37: 0 | AX37: =(F37*G$2)+(H37*I$2)+(J37*K$2)+(L37*M$2)+(N37*O$2)+(P37*Q$2)+(R37*S$2)+(T37*U$2)+(V37*W$2)+(X37*Y$2)+(Z37*AA$2)+(AB37*AC$2)+(AN37*AO$2)+(AP37*AQ$2)+(AR37*AS$2)+(AT37*AU$2)+(AV37*AW$2)+(AD37*AE$2)+(AF37*AG$2)+(AH37*AI$2)+(AJ37*$AK$2) -> 0 | AY37: =sum(F37:AK37) + sum(AN37:AW37) -> 0 | AZ37: 0 | BA37: =sum(AY37:AZ37) -> 0 | BB37: =iferror(AX37/BA37,"")
A38: Mon | B38: =B37+1 -> 45691 | C38: 2 | D38: Week 2 | F38: 30 | H38: 30 | J38: 0 | L38: 0 | N38: 0 | P38: 0 | R38: 230 | T38: 230 | V38: 0 | X38: 0 | Z38: 0 | AB38: 0 | AD38: 0 | AF38: 0 | AH38: 0 | AL38: 0 | AX38: =(F38*G$2)+(H38*I$2)+(J38*K$2)+(L38*M$2)+(N38*O$2)+(P38*Q$2)+(R38*S$2)+(T38*U$2)+(V38*W$2)+(X38*Y$2)+(Z38*AA$2)+(AB38*AC$2)+(AN38*AO$2)+(AP38*AQ$2)+(AR38*AS$2)+(AT38*AU$2)+(AV38*AW$2)+(AD38*AE$2)+(AF38*AG$2)+(AH38*AI$2)+(AJ38*$AK$2) -> 6450.2 | AY38: =sum(F38:AK38) + sum(AN38:AW38) -> 520 | AZ38: 0 | BA38: =sum(AY38:AZ38) -> 520 | BB38: =iferror(AX38/BA38,"") -> 12.404231
A39: Tue | B39: =B38+1 -> 45692 | C39: 2 | D39: Week 2 | F39: 30 | H39: 30 | J39: 0 | L39: 0 | N39: 0 | P39: 0 | R39: 230 | T39: 230 | V39: 0 | X39: 0 | Z39: 0 | AB39: 0 | AD39: 0 | AF39: 0 | AH39: 0 | AL39: 0 | AX39: =(F39*G$2)+(H39*I$2)+(J39*K$2)+(L39*M$2)+(N39*O$2)+(P39*Q$2)+(R39*S$2)+(T39*U$2)+(V39*W$2)+(X39*Y$2)+(Z39*AA$2)+(AB39*AC$2)+(AN39*AO$2)+(AP39*AQ$2)+(AR39*AS$2)+(AT39*AU$2)+(AV39*AW$2)+(AD39*AE$2)+(AF39*AG$2)+(AH39*AI$2)+(AJ39*$AK$2) -> 6450.2 | AY39: =sum(F39:AK39) + sum(AN39:AW39) -> 520 | AZ39: 0 | BA39: =sum(AY39:AZ39) -> 520 | BB39: =iferror(AX39/BA39,"") -> 12.404231
A40: Wed | B40: =B39+1 -> 45693 | C40: 2 | D40: Week 2 | F40: 30 | H40: 30 | J40: 0 | L40: 0 | N40: 0 | P40: 0 | R40: 230 | T40: 230 | V40: 0 | X40: 0 | Z40: 0 | AB40: 0 | AD40: 0 | AF40: 0 | AH40: 0 | AL40: 0 | AX40: =(F40*G$2)+(H40*I$2)+(J40*K$2)+(L40*M$2)+(N40*O$2)+(P40*Q$2)+(R40*S$2)+(T40*U$2)+(V40*W$2)+(X40*Y$2)+(Z40*AA$2)+(AB40*AC$2)+(AN40*AO$2)+(AP40*AQ$2)+(AR40*AS$2)+(AT40*AU$2)+(AV40*AW$2)+(AD40*AE$2)+(AF40*AG$2)+(AH40*AI$2)+(AJ40*$AK$2) -> 6450.2 | AY40: =sum(F40:AK40) + sum(AN40:AW40) -> 520 | AZ40: 0 | BA40: =sum(AY40:AZ40) -> 520 | BB40: =iferror(AX40/BA40,"") -> 12.404231
A41: Thurs | B41: =B40+1 -> 45694 | C41: 2 | D41: Week 2 | F41: 30 | H41: 30 | J41: 0 | L41: 0 | N41: 0 | P41: 0 | R41: 230 | T41: 230 | V41: 0 | X41: 0 | Z41: 0 | AB41: 0 | AD41: 0 | AF41: 0 | AH41: 0 | AL41: 0 | AX41: =(F41*G$2)+(H41*I$2)+(J41*K$2)+(L41*M$2)+(N41*O$2)+(P41*Q$2)+(R41*S$2)+(T41*U$2)+(V41*W$2)+(X41*Y$2)+(Z41*AA$2)+(AB41*AC$2)+(AN41*AO$2)+(AP41*AQ$2)+(AR41*AS$2)+(AT41*AU$2)+(AV41*AW$2)+(AD41*AE$2)+(AF41*AG$2)+(AH41*AI$2)+(AJ41*$AK$2) -> 6450.2 | AY41: =sum(F41:AK41) + sum(AN41:AW41) -> 520 | AZ41: 0 | BA41: =sum(AY41:AZ41) -> 520 | BB41: =iferror(AX41/BA41,"") -> 12.404231
A42: Fri | B42: =B41+1 -> 45695 | C42: 2 | D42: Week 2 | F42: 30 | H42: 30 | J42: 0 | L42: 0 | N42: 0 | P42: 0 | R42: 230 | T42: 230 | V42: 0 | X42: 0 | Z42: 0 | AB42: 0 | AD42: 0 | AF42: 0 | AH42: 0 | AL42: 0 | AX42: =(F42*G$2)+(H42*I$2)+(J42*K$2)+(L42*M$2)+(N42*O$2)+(P42*Q$2)+(R42*S$2)+(T42*U$2)+(V42*W$2)+(X42*Y$2)+(Z42*AA$2)+(AB42*AC$2)+(AN42*AO$2)+(AP42*AQ$2)+(AR42*AS$2)+(AT42*AU$2)+(AV42*AW$2)+(AD42*AE$2)+(AF42*AG$2)+(AH42*AI$2)+(AJ42*$AK$2) -> 6450.2 | AY42: =sum(F42:AK42) + sum(AN42:AW42) -> 520 | AZ42: 0 | BA42: =sum(AY42:AZ42) -> 520 | BB42: =iferror(AX42/BA42,"") -> 12.404231
A43: Sat | B43: =B42+1 -> 45696 | C43: 2 | D43: Week 2 | F43: 30 | H43: 30 | J43: 0 | L43: 0 | N43: 0 | P43: 0 | R43: 230 | T43: 230 | V43: 0 | X43: 0 | Z43: 0 | AB43: 0 | AD43: 0 | AF43: 0 | AH43: 0 | AL43: 0 | AX43: =(F43*G$2)+(H43*I$2)+(J43*K$2)+(L43*M$2)+(N43*O$2)+(P43*Q$2)+(R43*S$2)+(T43*U$2)+(V43*W$2)+(X43*Y$2)+(Z43*AA$2)+(AB43*AC$2)+(AN43*AO$2)+(AP43*AQ$2)+(AR43*AS$2)+(AT43*AU$2)+(AV43*AW$2)+(AD43*AE$2)+(AF43*AG$2)+(AH43*AI$2)+(AJ43*$AK$2) -> 6450.2 | AY43: =sum(F43:AK43) + sum(AN43:AW43) -> 520 | AZ43: 0 | BA43: =sum(AY43:AZ43) -> 520 | BB43: =iferror(AX43/BA43,"") -> 12.404231
A44: Sun | B44: =B43+1 -> 45697 | C44: 2 | D44: Week 2 | F44: 0 | H44: 0 | J44: 0 | L44: 0 | N44: 0 | P44: 0 | R44: 0 | T44: 0 | V44: 0 | X44: 0 | Z44: 0 | AB44: 0 | AD44: 0 | AF44: 0 | AH44: 0 | AL44: 0 | AX44: =(F44*G$2)+(H44*I$2)+(J44*K$2)+(L44*M$2)+(N44*O$2)+(P44*Q$2)+(R44*S$2)+(T44*U$2)+(V44*W$2)+(X44*Y$2)+(Z44*AA$2)+(AB44*AC$2)+(AN44*AO$2)+(AP44*AQ$2)+(AR44*AS$2)+(AT44*AU$2)+(AV44*AW$2)+(AD44*AE$2)+(AF44*AG$2)+(AH44*AI$2)+(AJ44*$AK$2) -> 0 | AY44: =sum(F44:AK44) + sum(AN44:AW44) -> 0 | AZ44: 0 | BA44: =sum(AY44:AZ44) -> 0 | BB44: =iferror(AX44/BA44,"")
A45: Mon | B45: =B44+1 -> 45698 | C45: 2 | D45: Week 3 | E45: SPRING TRAINING | F45: 110 | H45: 110 | J45: 0 | L45: 0 | N45: 0 | R45: 240 | T45: 240 | V45: 0 | X45: 0 | Z45: 0 | AB45: 0 | AD45: 0 | AF45: 0 | AH45: 0 | AL45: 0 | AX45: =(F45*G$2)+(H45*I$2)+(J45*K$2)+(L45*M$2)+(N45*O$2)+(P45*Q$2)+(R45*S$2)+(T45*U$2)+(V45*W$2)+(X45*Y$2)+(Z45*AA$2)+(AB45*AC$2)+(AN45*AO$2)+(AP45*AQ$2)+(AR45*AS$2)+(AT45*AU$2)+(AV45*AW$2)+(AD45*AE$2)+(AF45*AG$2)+(AH45*AI$2)+(AJ45*$AK$2) -> 10232.6 | AY45: =sum(F45:AK45) + sum(AN45:AW45) -> 700 | AZ45: 0 | BA45: =sum(AY45:AZ45) -> 700 | BB45: =iferror(AX45/BA45,"") -> 14.618
A46: Tue | B46: =B45+1 -> 45699 | C46: 2 | D46: Week 3 | F46: 110 | H46: 110 | J46: 0 | L46: 0 | N46: 0 | P46: 0 | R46: 240 | T46: 240 | V46: 0 | X46: 0 | Z46: 0 | AB46: 0 | AD46: 0 | AF46: 0 | AH46: 0 | AL46: 0 | AX46: =(F46*G$2)+(H46*I$2)+(J46*K$2)+(L46*M$2)+(N46*O$2)+(P46*Q$2)+(R46*S$2)+(T46*U$2)+(V46*W$2)+(X46*Y$2)+(Z46*AA$2)+(AB46*AC$2)+(AN46*AO$2)+(AP46*AQ$2)+(AR46*AS$2)+(AT46*AU$2)+(AV46*AW$2)+(AD46*AE$2)+(AF46*AG$2)+(AH46*AI$2)+(AJ46*$AK$2) -> 10232.6 | AY46: =sum(F46:AK46) + sum(AN46:AW46) -> 700 | AZ46: 0 | BA46: =sum(AY46:AZ46) -> 700 | BB46: =iferror(AX46/BA46,"") -> 14.618
A47: Wed | B47: =B46+1 -> 45700 | C47: 2 | D47: Week 3 | F47: 110 | H47: 110 | J47: 0 | L47: 0 | N47: 0 | P47: 0 | R47: 240 | T47: 240 | V47: 0 | X47: 0 | Z47: 0 | AB47: 0 | AD47: 0 | AF47: 0 | AH47: 0 | AL47: 0 | AX47: =(F47*G$2)+(H47*I$2)+(J47*K$2)+(L47*M$2)+(N47*O$2)+(P47*Q$2)+(R47*S$2)+(T47*U$2)+(V47*W$2)+(X47*Y$2)+(Z47*AA$2)+(AB47*AC$2)+(AN47*AO$2)+(AP47*AQ$2)+(AR47*AS$2)+(AT47*AU$2)+(AV47*AW$2)+(AD47*AE$2)+(AF47*AG$2)+(AH47*AI$2)+(AJ47*$AK$2) -> 10232.6 | AY47: =sum(F47:AK47) + sum(AN47:AW47) -> 700 | AZ47: 0 | BA47: =sum(AY47:AZ47) -> 700 | BB47: =iferror(AX47/BA47,"") -> 14.618
A48: Thurs | B48: =B47+1 -> 45701 | C48: 2 | D48: Week 3 | F48: 140 | H48: 140 | J48: 0 | L48: 0 | N48: 0 | P48: 0 | R48: 240 | T48: 240 | V48: 0 | X48: 0 | Z48: 0 | AB48: 0 | AD48: 0 | AF48: 0 | AH48: 0 | AL48: 0 | AX48: =(F48*G$2)+(H48*I$2)+(J48*K$2)+(L48*M$2)+(N48*O$2)+(P48*Q$2)+(R48*S$2)+(T48*U$2)+(V48*W$2)+(X48*Y$2)+(Z48*AA$2)+(AB48*AC$2)+(AN48*AO$2)+(AP48*AQ$2)+(AR48*AS$2)+(AT48*AU$2)+(AV48*AW$2)+(AD48*AE$2)+(AF48*AG$2)+(AH48*AI$2)+(AJ48*$AK$2) -> 11567.6 | AY48: =sum(F48:AK48) + sum(AN48:AW48) -> 760 | AZ48: 0 | BA48: =sum(AY48:AZ48) -> 760 | BB48: =iferror(AX48/BA48,"") -> 15.220526
A49: Fri | B49: =B48+1 -> 45702 | C49: 2 | D49: Week 3 | F49: 140 | H49: 140 | J49: 0 | L49: 0 | N49: 0 | P49: 0 | R49: 240 | T49: 240 | V49: 0 | X49: 0 | Z49: 0 | AB49: 0 | AD49: 0 | AF49: 0 | AH49: 0 | AL49: 0 | AX49: =(F49*G$2)+(H49*I$2)+(J49*K$2)+(L49*M$2)+(N49*O$2)+(P49*Q$2)+(R49*S$2)+(T49*U$2)+(V49*W$2)+(X49*Y$2)+(Z49*AA$2)+(AB49*AC$2)+(AN49*AO$2)+(AP49*AQ$2)+(AR49*AS$2)+(AT49*AU$2)+(AV49*AW$2)+(AD49*AE$2)+(AF49*AG$2)+(AH49*AI$2)+(AJ49*$AK$2) -> 11567.6 | AY49: =sum(F49:AK49) + sum(AN49:AW49) -> 760 | AZ49: 0 | BA49: =sum(AY49:AZ49) -> 760 | BB49: =iferror(AX49/BA49,"") -> 15.220526
A50: Sat | B50: =B49+1 -> 45703 | C50: 2 | D50: Week 3 | F50: 140 | H50: 140 | J50: 0 | L50: 0 | N50: 0 | P50: 0 | R50: 240 | T50: 240 | V50: 0 | X50: 0 | Z50: 0 | AB50: 0 | AD50: 0 | AF50: 0 | AH50: 0 | AL50: 0 | AX50: =(F50*G$2)+(H50*I$2)+(J50*K$2)+(L50*M$2)+(N50*O$2)+(P50*Q$2)+(R50*S$2)+(T50*U$2)+(V50*W$2)+(X50*Y$2)+(Z50*AA$2)+(AB50*AC$2)+(AN50*AO$2)+(AP50*AQ$2)+(AR50*AS$2)+(AT50*AU$2)+(AV50*AW$2)+(AD50*AE$2)+(AF50*AG$2)+(AH50*AI$2)+(AJ50*$AK$2) -> 11567.6 | AY50: =sum(F50:AK50) + sum(AN50:AW50) -> 760 | AZ50: 0 | BA50: =sum(AY50:AZ50) -> 760 | BB50: =iferror(AX50/BA50,"") -> 15.220526
A51: Sun | B51: =B50+1 -> 45704 | C51: 2 | D51: Week 3 | F51: 140 | H51: 140 | J51: 0 | L51: 0 | N51: 0 | P51: 0 | R51: 0 | T51: 0 | V51: 0 | X51: 0 | Z51: 0 | AB51: 0 | AD51: 0 | AF51: 0 | AH51: 0 | AL51: 0 | AX51: =(F51*G$2)+(H51*I$2)+(J51*K$2)+(L51*M$2)+(N51*O$2)+(P51*Q$2)+(R51*S$2)+(T51*U$2)+(V51*W$2)+(X51*Y$2)+(Z51*AA$2)+(AB51*AC$2)+(AN51*AO$2)+(AP51*AQ$2)+(AR51*AS$2)+(AT51*AU$2)+(AV51*AW$2)+(AD51*AE$2)+(AF51*AG$2)+(AH51*AI$2)+(AJ51*$AK$2) -> 6230 | AY51: =sum(F51:AK51) + sum(AN51:AW51) -> 280 | AZ51: 0 | BA51: =sum(AY51:AZ51) -> 280 | BB51: =iferror(AX51/BA51,"") -> 22.25
A52: Mon | B52: =B51+1 -> 45705 | C52: 2 | D52: Week 4 | F52: 140 | H52: 140 | J52: 0 | L52: 0 | N52: 0 | P52: 0 | R52: 246 | T52: 246 | V52: 0 | X52: 0 | Z52: 0 | AB52: 0 | AD52: 0 | AF52: 0 | AH52: 0 | AL52: 0 | AX52: =(F52*G$2)+(H52*I$2)+(J52*K$2)+(L52*M$2)+(N52*O$2)+(P52*Q$2)+(R52*S$2)+(T52*U$2)+(V52*W$2)+(X52*Y$2)+(Z52*AA$2)+(AB52*AC$2)+(AN52*AO$2)+(AP52*AQ$2)+(AR52*AS$2)+(AT52*AU$2)+(AV52*AW$2)+(AD52*AE$2)+(AF52*AG$2)+(AH52*AI$2)+(AJ52*$AK$2) -> 11701.04 | AY52: =sum(F52:AK52) + sum(AN52:AW52) -> 772 | AZ52: 0 | BA52: =sum(AY52:AZ52) -> 772 | BB52: =iferror(AX52/BA52,"") -> 15.156788
A53: Tue | B53: =B52+1 -> 45706 | C53: 2 | D53: Week 4 | F53: 150 | H53: 150 | J53: 0 | L53: 0 | N53: 0 | P53: 0 | R53: 246 | T53: 246 | V53: 0 | X53: 0 | Z53: 0 | AB53: 0 | AD53: 0 | AF53: 0 | AH53: 0 | AL53: 0 | AX53: =(F53*G$2)+(H53*I$2)+(J53*K$2)+(L53*M$2)+(N53*O$2)+(P53*Q$2)+(R53*S$2)+(T53*U$2)+(V53*W$2)+(X53*Y$2)+(Z53*AA$2)+(AB53*AC$2)+(AN53*AO$2)+(AP53*AQ$2)+(AR53*AS$2)+(AT53*AU$2)+(AV53*AW$2)+(AD53*AE$2)+(AF53*AG$2)+(AH53*AI$2)+(AJ53*$AK$2) -> 12146.04 | AY53: =sum(F53:AK53) + sum(AN53:AW53) -> 792 | AZ53: 0 | BA53: =sum(AY53:AZ53) -> 792 | BB53: =iferror(AX53/BA53,"") -> 15.335909
A54: Wed | B54: =B53+1 -> 45707 | C54: 2 | D54: Week 4 | F54: 150 | H54: 150 | J54: 0 | L54: 0 | N54: 0 | P54: 0 | R54: 246 | T54: 246 | V54: 0 | X54: 0 | Z54: 0 | AB54: 0 | AD54: 0 | AF54: 0 | AH54: 0 | AL54: 0 | AX54: =(F54*G$2)+(H54*I$2)+(J54*K$2)+(L54*M$2)+(N54*O$2)+(P54*Q$2)+(R54*S$2)+(T54*U$2)+(V54*W$2)+(X54*Y$2)+(Z54*AA$2)+(AB54*AC$2)+(AN54*AO$2)+(AP54*AQ$2)+(AR54*AS$2)+(AT54*AU$2)+(AV54*AW$2)+(AD54*AE$2)+(AF54*AG$2)+(AH54*AI$2)+(AJ54*$AK$2) -> 12146.04 | AY54: =sum(F54:AK54) + sum(AN54:AW54) -> 792 | AZ54: 0 | BA54: =sum(AY54:AZ54) -> 792 | BB54: =iferror(AX54/BA54,"") -> 15.335909
...

Sheet Actuals - Billing - 2025
A1: Toronto Blue Jays @ Dunedin, FL | F1: Major League - PDC | R1: Kirk | T1: Minor League - PDC | AF1: Single A Jays | AL1: SSM | AN1: Other | BB1: TOTALS
A2: Day | B2: Date | C2: Period | D2: Week | E2: Camp Name | F2: Breakfast | G2: 22.25 | H2: Lunch | I2: 22.25 | J2: Dinner | K2: 22.25 | L2: Umpire | M2: 22.25 | N2: Post Game Meal | O2: 22.25 | P2: Snack | Q2: 1.64 | R2: Individual Player Meals - Kirk | S2: 22.88 | T2: Breakfast -Mi | U2: 11.12 | V2: Lunch -Mi | W2: 11.12 | X2: Dinner - Mi | Y2: 11.12 | Z2: Individual Player Meals - Invoice to Michelle Separately | AA2: 11.12 | AB2: Florida Ops | AC2: 11.12 | AD2: SCOUTS - Invoice to Michelle Separately | AE2: 11.12 | AF2: Breakfast - A | AG2: 15.89 | AH2: PRE-GAME - A | AI2: 15.89 | AJ2: POST-GAME - A | AK2: 15.89 | AL2: Stadium Staff Meals | AM2: 15.89 | AN2: Fun $$$$ Allocated | AO2: 27404 | AP2: Media Meals | AQ2: 15 | AR2: MLB G&G - Pantry | AS2: 1.64 | AT2: MiLB G&G - Pantry | AU2: 1.64 | AV2: MLB - Catering | AW2: 35 | AX2: Team Canada - Home | AY2: 11.12 | AZ2: Team Canada - Road | BA2: 15.89 | BB2: Total Revenue | BC2: Total Meals | BD2: Total Snacks | BE2: Total Charged Items | BF2: Average $/Item | BG2: Invoice Date
A3: Mon | B3: 45656 | C3: 1 | D3: Week 1 | E3: CLOSED | H3: 0 | BB3: =(F3*G$2)+(H3*I$2)+(J3*K$2)+(L3*M$2)+(N3*O$2)+(P3*Q$2)+(T3*U$2)+(V3*W$2)+(X3*Y$2)+(Z3*AA$2)+(AB3*AC$2)+(AD3*AE$2)+(AP3*AQ$2)+(AR3*AS$2)+(AT3*AU$2)+(AV3*AW$2)+(AX3*AY$2)+(AF3*AG$2)+(AH3*AI$2)+(AJ3*AK$2)+(AL3*$AM$2)+(R3*$S$2) -> 0 | BC3: =sum(F3:AM3) + sum(AP3:AY3) -> 0 | BD3: =0 -> 0 | BE3: =BC3 -> 0 | BF3: =iferror(BB3/BE3,"")
A4: Tue | B4: =B3+1 -> 45657 | C4: 1 | D4: Week 1 | E4: NEW YEAR'S EVE | BB4: =(F4*G$2)+(H4*I$2)+(J4*K$2)+(L4*M$2)+(N4*O$2)+(P4*Q$2)+(T4*U$2)+(V4*W$2)+(X4*Y$2)+(Z4*AA$2)+(AB4*AC$2)+(AD4*AE$2)+(AP4*AQ$2)+(AR4*AS$2)+(AT4*AU$2)+(AV4*AW$2)+(AX4*AY$2)+(AF4*AG$2)+(AH4*AI$2)+(AJ4*AK$2)+(AL4*$AM$2)+(R4*$S$2) -> 0 | BC4: =sum(F4:AM4) + sum(AP4:AY4) -> 0 | BD4: =0 -> 0 | BE4: =BC4 -> 0 | BF4: =iferror(BB4/BE4,"")
A5: Wed | B5: =B4+1 -> 45658 | C5: 1 | D5: Week 1 | E5: NEW YEAR'S DAY | BB5: =(F5*G$2)+(H5*I$2)+(J5*K$2)+(L5*M$2)+(N5*O$2)+(P5*Q$2)+(T5*U$2)+(V5*W$2)+(X5*Y$2)+(Z5*AA$2)+(AB5*AC$2)+(AD5*AE$2)+(AP5*AQ$2)+(AR5*AS$2)+(AT5*AU$2)+(AV5*AW$2)+(AX5*AY$2)+(AF5*AG$2)+(AH5*AI$2)+(AJ5*AK$2)+(AL5*$AM$2)+(R5*$S$2) -> 0 | BC5: =sum(F5:AM5) + sum(AP5:AY5) -> 0 | BD5: =0 -> 0 | BE5: =BC5 -> 0 | BF5: =iferror(BB5/BE5,"")
A6: Thurs | B6: =B5+1 -> 45659 | C6: 1 | D6: Week 1 | E6: CLOSED | BB6: =(F6*G$2)+(H6*I$2)+(J6*K$2)+(L6*M$2)+(N6*O$2)+(P6*Q$2)+(T6*U$2)+(V6*W$2)+(X6*Y$2)+(Z6*AA$2)+(AB6*AC$2)+(AD6*AE$2)+(AP6*AQ$2)+(AR6*AS$2)+(AT6*AU$2)+(AV6*AW$2)+(AX6*AY$2)+(AF6*AG$2)+(AH6*AI$2)+(AJ6*AK$2)+(AL6*$AM$2)+(R6*$S$2) -> 0 | BC6: =sum(F6:AM6) + sum(AP6:AY6) -> 0 | BD6: =0 -> 0 | BE6: =BC6 -> 0 | BF6: =iferror(BB6/BE6,"")
A7: Fri | B7: =B6+1 -> 45660 | C7: 1 | D7: Week 1 | E7: CLOSED | BB7: =(F7*G$2)+(H7*I$2)+(J7*K$2)+(L7*M$2)+(N7*O$2)+(P7*Q$2)+(T7*U$2)+(V7*W$2)+(X7*Y$2)+(Z7*AA$2)+(AB7*AC$2)+(AD7*AE$2)+(AP7*AQ$2)+(AR7*AS$2)+(AT7*AU$2)+(AV7*AW$2)+(AX7*AY$2)+(AF7*AG$2)+(AH7*AI$2)+(AJ7*AK$2)+(AL7*$AM$2)+(R7*$S$2) -> 0 | BC7: =sum(F7:AM7) + sum(AP7:AY7) -> 0 | BD7: =0 -> 0 | BE7: =BC7 -> 0 | BF7: =iferror(BB7/BE7,"")
A8: Sat | B8: =B7+1 -> 45661 | C8: 1 | D8: Week 1 | E8: CLOSED | BB8: =(F8*G$2)+(H8*I$2)+(J8*K$2)+(L8*M$2)+(N8*O$2)+(P8*Q$2)+(T8*U$2)+(V8*W$2)+(X8*Y$2)+(Z8*AA$2)+(AB8*AC$2)+(AD8*AE$2)+(AP8*AQ$2)+(AR8*AS$2)+(AT8*AU$2)+(AV8*AW$2)+(AX8*AY$2)+(AF8*AG$2)+(AH8*AI$2)+(AJ8*AK$2)+(AL8*$AM$2)+(R8*$S$2) -> 0 | BC8: =sum(F8:AM8) + sum(AP8:AY8) -> 0 | BD8: =0 -> 0 | BE8: =BC8 -> 0 | BF8: =iferror(BB8/BE8,"")
A9: Sun | B9: =B8+1 -> 45662 | C9: 1 | D9: Week 1 | E9: CLOSED | BB9: =(F9*G$2)+(H9*I$2)+(J9*K$2)+(L9*M$2)+(N9*O$2)+(P9*Q$2)+(T9*U$2)+(V9*W$2)+(X9*Y$2)+(Z9*AA$2)+(AB9*AC$2)+(AD9*AE$2)+(AP9*AQ$2)+(AR9*AS$2)+(AT9*AU$2)+(AV9*AW$2)+(AX9*AY$2)+(AF9*AG$2)+(AH9*AI$2)+(AJ9*AK$2)+(AL9*$AM$2)+(R9*$S$2) -> 0 | BC9: =sum(F9:AM9) + sum(AP9:AY9) -> 0 | BD9: =0 -> 0 | BE9: =BC9 -> 0 | BF9: =iferror(BB9/BE9,"")
A10: Mon | B10: =B9+1 -> 45663 | C10: 1 | D10: Week 2 | E10: FIRST DAY OF 2025 | F10: 0 | H10: 0 | J10: 0 | L10: 0 | N10: 0 | P10: 0 | T10: 92 | V10: 92 | X10: 0 | Z10: 0 | AB10: 0 | AD10: 0 | AF10: 0 | AH10: 0 | AJ10: 0 | AL10: 0 | AP10: 0 | AR10: 0 | AT10: 0 | AV10: 0 | AX10: 0 | AZ10: 0 | BB10: =(F10*G$2)+(H10*I$2)+(J10*K$2)+(L10*M$2)+(N10*O$2)+(P10*Q$2)+(T10*U$2)+(V10*W$2)+(X10*Y$2)+(Z10*AA$2)+(AB10*AC$2)+(AD10*AE$2)+(AP10*AQ$2)+(AR10*AS$2)+(AT10*AU$2)+(AV10*AW$2)+(AX10*AY$2)+(AF10*AG$2)+(AH10*AI$2)+(AJ10*AK$2)+(AL10*$AM$2)+(R10*$S$2) -> 2046.08 | BC10: =sum(F10:AM10) + sum(AP10:AY10) -> 184 | BD10: =0 -> 0 | BE10: =BC10 -> 184 | BF10: =iferror(BB10/BE10,"") -> 11.12
A11: Tue | B11: =B10+1 -> 45664 | C11: 1 | D11: Week 2 | F11: 0 | H11: 0 | J11: 0 | L11: 0 | N11: 0 | P11: 0 | T11: 92 | V11: 92 | X11: 0 | Z11: 0 | AB11: 0 | AD11: 0 | AF11: 0 | AH11: 0 | AJ11: 0 | AL11: 0 | AP11: 0 | AR11: 0 | AT11: 0 | AV11: 0 | AX11: 0 | AZ11: 0 | BB11: =(F11*G$2)+(H11*I$2)+(J11*K$2)+(L11*M$2)+(N11*O$2)+(P11*Q$2)+(T11*U$2)+(V11*W$2)+(X11*Y$2)+(Z11*AA$2)+(AB11*AC$2)+(AD11*AE$2)+(AP11*AQ$2)+(AR11*AS$2)+(AT11*AU$2)+(AV11*AW$2)+(AX11*AY$2)+(AF11*AG$2)+(AH11*AI$2)+(AJ11*AK$2)+(AL11*$AM$2)+(R11*$S$2) -> 2046.08 | BC11: =sum(F11:AM11) + sum(AP11:AY11) -> 184 | BD11: =0 -> 0 | BE11: =BC11 -> 184 | BF11: =iferror(BB11/BE11,"") -> 11.12
A12: Wed | B12: =B11+1 -> 45665 | C12: 1 | D12: Week 2 | F12: 0 | H12: 0 | J12: 0 | L12: 0 | N12: 0 | P12: 0 | T12: 92 | V12: 92 | X12: 0 | Z12: 0 | AB12: 0 | AD12: 0 | AF12: 0 | AH12: 0 | AJ12: 0 | AL12: 0 | AP12: 0 | AR12: 0 | AT12: 0 | AV12: 0 | AX12: 0 | AZ12: 0 | BB12: =(F12*G$2)+(H12*I$2)+(J12*K$2)+(L12*M$2)+(N12*O$2)+(P12*Q$2)+(T12*U$2)+(V12*W$2)+(X12*Y$2)+(Z12*AA$2)+(AB12*AC$2)+(AD12*AE$2)+(AP12*AQ$2)+(AR12*AS$2)+(AT12*AU$2)+(AV12*AW$2)+(AX12*AY$2)+(AF12*AG$2)+(AH12*AI$2)+(AJ12*AK$2)+(AL12*$AM$2)+(R12*$S$2) -> 2046.08 | BC12: =sum(F12:AM12) + sum(AP12:AY12) -> 184 | BD12: =0 -> 0 | BE12: =BC12 -> 184 | BF12: =iferror(BB12/BE12,"") -> 11.12
A13: Thurs | B13: =B12+1 -> 45666 | C13: 1 | D13: Week 2 | F13: 0 | H13: 0 | J13: 0 | L13: 0 | N13: 0 | P13: 0 | T13: 92 | V13: 92 | X13: 0 | Z13: 0 | AB13: 0 | AD13: 0 | AF13: 0 | AH13: 0 | AJ13: 0 | AL13: 0 | AP13: 0 | AR13: 0 | AT13: 0 | AV13: 0 | AX13: 0 | AZ13: 0 | BB13: =(F13*G$2)+(H13*I$2)+(J13*K$2)+(L13*M$2)+(N13*O$2)+(P13*Q$2)+(T13*U$2)+(V13*W$2)+(X13*Y$2)+(Z13*AA$2)+(AB13*AC$2)+(AD13*AE$2)+(AP13*AQ$2)+(AR13*AS$2)+(AT13*AU$2)+(AV13*AW$2)+(AX13*AY$2)+(AF13*AG$2)+(AH13*AI$2)+(AJ13*AK$2)+(AL13*$AM$2)+(R13*$S$2) -> 2046.08 | BC13: =sum(F13:AM13) + sum(AP13:AY13) -> 184 | BD13: =0 -> 0 | BE13: =BC13 -> 184 | BF13: =iferror(BB13/BE13,"") -> 11.12
A14: Fri | B14: =B13+1 -> 45667 | C14: 1 | D14: Week 2 | F14: 0 | H14: 0 | J14: 0 | L14: 0 | N14: 0 | P14: 0 | T14: 92 | V14: 92 | X14: 0 | Z14: 0 | AB14: 0 | AD14: 0 | AF14: 0 | AH14: 0 | AJ14: 0 | AL14: 0 | AP14: 0 | AR14: 0 | AT14: 0 | AV14: 0 | AX14: 0 | AZ14: 0 | BB14: =(F14*G$2)+(H14*I$2)+(J14*K$2)+(L14*M$2)+(N14*O$2)+(P14*Q$2)+(T14*U$2)+(V14*W$2)+(X14*Y$2)+(Z14*AA$2)+(AB14*AC$2)+(AD14*AE$2)+(AP14*AQ$2)+(AR14*AS$2)+(AT14*AU$2)+(AV14*AW$2)+(AX14*AY$2)+(AF14*AG$2)+(AH14*AI$2)+(AJ14*AK$2)+(AL14*$AM$2)+(R14*$S$2) -> 2046.08 | BC14: =sum(F14:AM14) + sum(AP14:AY14) -> 184 | BD14: =0 -> 0 | BE14: =BC14 -> 184 | BF14: =iferror(BB14/BE14,"") -> 11.12
A15: Sat | B15: =B14+1 -> 45668 | C15: 1 | D15: Week 2 | F15: 0 | H15: 0 | J15: 0 | L15: 0 | N15: 0 | P15: 0 | T15: 0 | V15: 0 | X15: 0 | Z15: 0 | AB15: 0 | AD15: 0 | AF15: 0 | AH15: 0 | AJ15: 0 | AL15: 0 | AP15: 0 | AR15: 0 | AT15: 0 | AV15: 0 | AX15: 0 | AZ15: 0 | BB15: =(F15*G$2)+(H15*I$2)+(J15*K$2)+(L15*M$2)+(N15*O$2)+(P15*Q$2)+(T15*U$2)+(V15*W$2)+(X15*Y$2)+(Z15*AA$2)+(AB15*AC$2)+(AD15*AE$2)+(AP15*AQ$2)+(AR15*AS$2)+(AT15*AU$2)+(AV15*AW$2)+(AX15*AY$2)+(AF15*AG$2)+(AH15*AI$2)+(AJ15*AK$2)+(AL15*$AM$2)+(R15*$S$2) -> 0 | BC15: =sum(F15:AM15) + sum(AP15:AY15) -> 0 | BD15: =0 -> 0 | BE15: =BC15 -> 0 | BF15: =iferror(BB15/BE15,"")
A16: Sun | B16: =B15+1 -> 45669 | C16: 1 | D16: Week 2 | F16: 0 | H16: 0 | J16: 0 | L16: 0 | N16: 0 | P16: 0 | T16: 0 | V16: 0 | X16: 0 | Z16: 0 | AB16: 0 | AD16: 0 | AF16: 0 | AH16: 0 | AJ16: 0 | AL16: 0 | AP16: 0 | AR16: 0 | AT16: 0 | AV16: 0 | AX16: 0 | AZ16: 0 | BB16: =(F16*G$2)+(H16*I$2)+(J16*K$2)+(L16*M$2)+(N16*O$2)+(P16*Q$2)+(T16*U$2)+(V16*W$2)+(X16*Y$2)+(Z16*AA$2)+(AB16*AC$2)+(AD16*AE$2)+(AP16*AQ$2)+(AR16*AS$2)+(AT16*AU$2)+(AV16*AW$2)+(AX16*AY$2)+(AF16*AG$2)+(AH16*AI$2)+(AJ16*AK$2)+(AL16*$AM$2)+(R16*$S$2) -> 0 | BC16: =sum(F16:AM16) + sum(AP16:AY16) -> 0 | BD16: =0 -> 0 | BE16: =BC16 -> 0 | BF16: =iferror(BB16/BE16,"")
A17: Mon | B17: =B16+1 -> 45670 | C17: 1 | D17: Week 3 | F17: 25 | H17: 25 | J17: 0 | L17: 0 | N17: 0 | P17: 0 | T17: 92 | V17: 92 | X17: 0 | Z17: 0 | AB17: 0 | AD17: 0 | AF17: 0 | AH17: 0 | AJ17: 0 | AL17: 0 | AP17: 0 | AR17: 0 | AT17: 0 | AV17: 0 | AX17: 0 | AZ17: 0 | BB17: =(F17*G$2)+(H17*I$2)+(J17*K$2)+(L17*M$2)+(N17*O$2)+(P17*Q$2)+(T17*U$2)+(V17*W$2)+(X17*Y$2)+(Z17*AA$2)+(AB17*AC$2)+(AD17*AE$2)+(AP17*AQ$2)+(AR17*AS$2)+(AT17*AU$2)+(AV17*AW$2)+(AX17*AY$2)+(AF17*AG$2)+(AH17*AI$2)+(AJ17*AK$2)+(AL17*$AM$2)+(R17*$S$2) -> 3158.58 | BC17: =sum(F17:AM17) + sum(AP17:AY17) -> 234 | BD17: =0 -> 0 | BE17: =BC17 -> 234 | BF17: =iferror(BB17/BE17,"") -> 13.498205
A18: Tue | B18: =B17+1 -> 45671 | C18: 1 | D18: Week 3 | F18: 25 | H18: 25 | J18: 0 | L18: 0 | N18: 0 | P18: 0 | T18: 92 | V18: 92 | X18: 0 | Z18: 0 | AB18: 0 | AD18: 0 | AF18: 0 | AH18: 0 | AJ18: 0 | AL18: 0 | AP18: 0 | AR18: 0 | AT18: 0 | AV18: 0 | AX18: 0 | AZ18: 0 | BB18: =(F18*G$2)+(H18*I$2)+(J18*K$2)+(L18*M$2)+(N18*O$2)+(P18*Q$2)+(T18*U$2)+(V18*W$2)+(X18*Y$2)+(Z18*AA$2)+(AB18*AC$2)+(AD18*AE$2)+(AP18*AQ$2)+(AR18*AS$2)+(AT18*AU$2)+(AV18*AW$2)+(AX18*AY$2)+(AF18*AG$2)+(AH18*AI$2)+(AJ18*AK$2)+(AL18*$AM$2)+(R18*$S$2) -> 3158.58 | BC18: =sum(F18:AM18) + sum(AP18:AY18) -> 234 | BD18: =0 -> 0 | BE18: =BC18 -> 234 | BF18: =iferror(BB18/BE18,"") -> 13.498205
A19: Wed | B19: =B18+1 -> 45672 | C19: 1 | D19: Week 3 | F19: 25 | H19: 25 | J19: 0 | L19: 0 | N19: 0 | P19: 0 | T19: 92 | V19: 92 | X19: 0 | Z19: 0 | AB19: 0 | AD19: 0 | AF19: 0 | AH19: 0 | AJ19: 0 | AL19: 0 | AP19: 0 | AR19: 0 | AT19: 0 | AV19: 0 | AX19: 0 | AZ19: 0 | BB19: =(F19*G$2)+(H19*I$2)+(J19*K$2)+(L19*M$2)+(N19*O$2)+(P19*Q$2)+(T19*U$2)+(V19*W$2)+(X19*Y$2)+(Z19*AA$2)+(AB19*AC$2)+(AD19*AE$2)+(AP19*AQ$2)+(AR19*AS$2)+(AT19*AU$2)+(AV19*AW$2)+(AX19*AY$2)+(AF19*AG$2)+(AH19*AI$2)+(AJ19*AK$2)+(AL19*$AM$2)+(R19*$S$2) -> 3158.58 | BC19: =sum(F19:AM19) + sum(AP19:AY19) -> 234 | BD19: =0 -> 0 | BE19: =BC19 -> 234 | BF19: =iferror(BB19/BE19,"") -> 13.498205
A20: Thurs | B20: =B19+1 -> 45673 | C20: 1 | D20: Week 3 | F20: 25 | H20: 25 | J20: 0 | L20: 0 | N20: 0 | P20: 0 | T20: 92 | V20: 92 | X20: 0 | Z20: 0 | AB20: 0 | AD20: 0 | AF20: 0 | AH20: 0 | AJ20: 0 | AL20: 0 | AP20: 0 | AR20: 0 | AT20: 0 | AV20: 0 | AX20: 0 | AZ20: 0 | BB20: =(F20*G$2)+(H20*I$2)+(J20*K$2)+(L20*M$2)+(N20*O$2)+(P20*Q$2)+(T20*U$2)+(V20*W$2)+(X20*Y$2)+(Z20*AA$2)+(AB20*AC$2)+(AD20*AE$2)+(AP20*AQ$2)+(AR20*AS$2)+(AT20*AU$2)+(AV20*AW$2)+(AX20*AY$2)+(AF20*AG$2)+(AH20*AI$2)+(AJ20*AK$2)+(AL20*$AM$2)+(R20*$S$2) -> 3158.58 | BC20: =sum(F20:AM20) + sum(AP20:AY20) -> 234 | BD20: =0 -> 0 | BE20: =BC20 -> 234 | BF20: =iferror(BB20/BE20,"") -> 13.498205
A21: Fri | B21: =B20+1 -> 45674 | C21: 1 | D21: Week 3 | F21: 25 | H21: 25 | J21: 0 | L21: 0 | N21: 0 | P21: 0 | T21: 107 | V21: 107 | X21: 0 | Z21: 0 | AB21: 0 | AD21: 0 | AF21: 0 | AH21: 0 | AJ21: 0 | AL21: 0 | AP21: 0 | AR21: 0 | AT21: 0 | AV21: 0 | AX21: 0 | AZ21: 0 | BB21: =(F21*G$2)+(H21*I$2)+(J21*K$2)+(L21*M$2)+(N21*O$2)+(P21*Q$2)+(T21*U$2)+(V21*W$2)+(X21*Y$2)+(Z21*AA$2)+(AB21*AC$2)+(AD21*AE$2)+(AP21*AQ$2)+(AR21*AS$2)+(AT21*AU$2)+(AV21*AW$2)+(AX21*AY$2)+(AF21*AG$2)+(AH21*AI$2)+(AJ21*AK$2)+(AL21*$AM$2)+(R21*$S$2) -> 3492.18 | BC21: =sum(F21:AM21) + sum(AP21:AY21) -> 264 | BD21: =0 -> 0 | BE21: =BC21 -> 264 | BF21: =iferror(BB21/BE21,"") -> 13.227955
A22: Sat | B22: =B21+1 -> 45675 | C22: 1 | D22: Week 3 | F22: 0 | H22: 0 | J22: 0 | L22: 0 | N22: 0 | P22: 0 | T22: 0 | V22: 0 | X22: 0 | Z22: 0 | AB22: 0 | AD22: 0 | AF22: 0 | AH22: 0 | AJ22: 0 | AL22: 0 | AP22: 0 | AR22: 0 | AT22: 0 | AV22: 0 | AX22: 0 | AZ22: 0 | BB22: =(F22*G$2)+(H22*I$2)+(J22*K$2)+(L22*M$2)+(N22*O$2)+(P22*Q$2)+(T22*U$2)+(V22*W$2)+(X22*Y$2)+(Z22*AA$2)+(AB22*AC$2)+(AD22*AE$2)+(AP22*AQ$2)+(AR22*AS$2)+(AT22*AU$2)+(AV22*AW$2)+(AX22*AY$2)+(AF22*AG$2)+(AH22*AI$2)+(AJ22*AK$2)+(AL22*$AM$2)+(R22*$S$2) -> 0 | BC22: =sum(F22:AM22) + sum(AP22:AY22) -> 0 | BD22: =0 -> 0 | BE22: =BC22 -> 0 | BF22: =iferror(BB22/BE22,"")
... A26: Wed | B26: =B25+1 -> 45679 | C26: 1 | D26: Week 4 | F26: 40 | H26: 40 | J26: 0 | L26: 0 | N26: 0 | P26: 0 | T26: 165 | V26: 165 | X26: 0 | Z26: 0 | AB26: 0 | AD26: 30 | AF26: 0 | AH26: 0 | AJ26: 0 | AL26: 0 | AP26: 0 | AR26: 0 | AT26: 0 | AV26: 0 | AX26: 0 | AZ26: 0 | BB26: =(F26*G$2)+(H26*I$2)+(J26*K$2)+(L26*M$2)+(N26*O$2)+(P26*Q$2)+(T26*U$2)+(V26*W$2)+(X26*Y$2)+(Z26*AA$2)+(AB26*AC$2)+(AD26*AE$2)+(AP26*AQ$2)+(AR26*AS$2)+(AT26*AU$2)+(AV26*AW$2)+(AX26*AY$2)+(AF26*AG$2)+(AH26*AI$2)+(AJ26*AK$2)+(AL26*$AM$2)+(R26*$S$2) -> 5783.2 | BC26: =sum(F26:AM26) + sum(AP26:AY26) -> 440 | BD26: =0 -> 0 | BE26: =BC26 -> 440 | BF26: =iferror(BB26/BE26,"") -> 13.143636
A27: Thurs | B27: =B26+1 -> 45680 | C27: 1 | D27: Week 4 | F27: 40 | H27: 40 | J27: 0 | L27: 0 | N27: 0 | P27: 0 | R27: 1 | T27: 165 | V27: 165 | X27: 0 | Z27: 0 | AB27: 0 | AD27: 30 | AF27: 0 | AH27: 0 | AJ27: 0 | AL27: 0 | AP27: 0 | AR27: 0 | AT27: 0 | AV27: 0 | AX27: 0 | AZ27: 0 | BB27: =(F27*G$2)+(H27*I$2)+(J27*K$2)+(L27*M$2)+(N27*O$2)+(P27*Q$2)+(T27*U$2)+(V27*W$2)+(X27*Y$2)+(Z27*AA$2)+(AB27*AC$2)+(AD27*AE$2)+(AP27*AQ$2)+(AR27*AS$2)+(AT27*AU$2)+(AV27*AW$2)+(AX27*AY$2)+(AF27*AG$2)+(AH27*AI$2)+(AJ27*AK$2)+(AL27*$AM$2)+(R27*$S$2) -> 5806.08 | BC27: =sum(F27:AM27) + sum(AP27:AY27) -> 441 | BD27: =0 -> 0 | BE27: =BC27 -> 441 | BF27: =iferror(BB27/BE27,"") -> 13.165714
A28: Fri | B28: =B27+1 -> 45681 | C28: 1 | D28: Week 4 | F28: 40 | H28: 40 | J28: 0 | L28: 0 | N28: 0 | P28: 0 | R28: 1 | T28: 165 | V28: 165 | X28: 0 | Z28: 0 | AB28: 0 | AD28: 30 | AF28: 0 | AH28: 0 | AJ28: 0 | AL28: 0 | AP28: 0 | AR28: 0 | AT28: 0 | AV28: 0 | AX28: 0 | AZ28: 0 | BB28: =(F28*G$2)+(H28*I$2)+(J28*K$2)+(L28*M$2)+(N28*O$2)+(P28*Q$2)+(T28*U$2)+(V28*W$2)+(X28*Y$2)+(Z28*AA$2)+(AB28*AC$2)+(AD28*AE$2)+(AP28*AQ$2)+(AR28*AS$2)+(AT28*AU$2)+(AV28*AW$2)+(AX28*AY$2)+(AF28*AG$2)+(AH28*AI$2)+(AJ28*AK$2)+(AL28*$AM$2)+(R28*$S$2) -> 5806.08 | BC28: =sum(F28:AM28) + sum(AP28:AY28) -> 441 | BD28: =0 -> 0 | BE28: =BC28 -> 441 | BF28: =iferror(BB28/BE28,"") -> 13.165714
A29: Sat | B29: =B28+1 -> 45682 | C29: 1 | D29: Week 4 | F29: 0 | H29: 0 | J29: 0 | L29: 0 | N29: 0 | P29: 0 | R29: 2 | T29: 0 | V29: 0 | X29: 0 | Z29: 0 | AB29: 0 | AD29: 0 | AF29: 0 | AH29: 0 | AJ29: 0 | AL29: 0 | AP29: 0 | AR29: 0 | AT29: 0 | AV29: 0 | AX29: 0 | AZ29: 0 | BB29: =(F29*G$2)+(H29*I$2)+(J29*K$2)+(L29*M$2)+(N29*O$2)+(P29*Q$2)+(T29*U$2)+(V29*W$2)+(X29*Y$2)+(Z29*AA$2)+(AB29*AC$2)+(AD29*AE$2)+(AP29*AQ$2)+(AR29*AS$2)+(AT29*AU$2)+(AV29*AW$2)+(AX29*AY$2)+(AF29*AG$2)+(AH29*AI$2)+(AJ29*AK$2)+(AL29*$AM$2)+(R29*$S$2) -> 45.76 | BC29: =sum(F29:AM29) + sum(AP29:AY29) -> 2 | BD29: =0 -> 0 | BE29: =BC29 -> 2 | BF29: =iferror(BB29/BE29,"") -> 22.88
A30: Sun | B30: =B29+1 -> 45683 | C30: 1 | D30: Week 4 | F30: 0 | H30: 0 | J30: 0 | L30: 0 | N30: 0 | P30: 0 | R30: 2 | T30: 0 | V30: 0 | X30: 0 | Z30: 0 | AB30: 0 | AD30: 0 | AF30: 0 | AH30: 0 | AJ30: 0 | AL30: 0 | AP30: 0 | AR30: 0 | AT30: 0 | AV30: 0 | AX30: 0 | AZ30: 0 | BB30: =(F30*G$2)+(H30*I$2)+(J30*K$2)+(L30*M$2)+(N30*O$2)+(P30*Q$2)+(T30*U$2)+(V30*W$2)+(X30*Y$2)+(Z30*AA$2)+(AB30*AC$2)+(AD30*AE$2)+(AP30*AQ$2)+(AR30*AS$2)+(AT30*AU$2)+(AV30*AW$2)+(AX30*AY$2)+(AF30*AG$2)+(AH30*AI$2)+(AJ30*AK$2)+(AL30*$AM$2)+(R30*$S$2) -> 45.76 | BC30: =sum(F30:AM30) + sum(AP30:AY30) -> 2 | BD30: =0 -> 0 | BE30: =BC30 -> 2 | BF30: =iferror(BB30/BE30,"") -> 22.88
A31: Mon | B31: =B30+1 -> 45684 | C31: 2 | D31: Week 1 | F31: 60 | H31: 60 | J31: 0 | L31: 0 | N31: 0 | P31: 0 | R31: 1 | T31: 160 | V31: 160 | X31: 0 | Z31: 0 | AB31: 0 | AD31: 0 | AF31: 0 | AH31: 0 | AJ31: 0 | AL31: 0 | AP31: 0 | AR31: 0 | AT31: 175 | AV31: 0 | AX31: 0 | AZ31: 0 | BB31: =(F31*G$2)+(H31*I$2)+(J31*K$2)+(L31*M$2)+(N31*O$2)+(P31*Q$2)+(T31*U$2)+(V31*W$2)+(X31*Y$2)+(Z31*AA$2)+(AB31*AC$2)+(AD31*AE$2)+(AP31*AQ$2)+(AR31*AS$2)+(AT31*AU$2)+(AV31*AW$2)+(AX31*AY$2)+(AF31*AG$2)+(AH31*AI$2)+(AJ31*AK$2)+(AL31*$AM$2)+(R31*$S$2) -> 6538.28 | BC31: =sum(F31:AM31) + sum(AP31:AY31) -> 616 | BD31: =0 -> 0 | BE31: =BC31 -> 616 | BF31: =iferror(BB31/BE31,"") -> 10.614091
A32: Tue | B32: =B31+1 -> 45685 | C32: 2 | D32: Week 1 | F32: 60 | H32: 60 | J32: 0 | L32: 0 | N32: 0 | P32: 0 | R32: 1 | T32: 160 | V32: 160 | X32: 0 | Z32: 0 | AB32: 0 | AD32: 0 | AF32: 0 | AH32: 0 | AJ32: 0 | AL32: 0 | AP32: 0 | AR32: 0 | AT32: 0 | AV32: 0 | AX32: 0 | AZ32: 0 | BB32: =(F32*G$2)+(H32*I$2)+(J32*K$2)+(L32*M$2)+(N32*O$2)+(P32*Q$2)+(T32*U$2)+(V32*W$2)+(X32*Y$2)+(Z32*AA$2)+(AB32*AC$2)+(AD32*AE$2)+(AP32*AQ$2)+(AR32*AS$2)+(AT32*AU$2)+(AV32*AW$2)+(AX32*AY$2)+(AF32*AG$2)+(AH32*AI$2)+(AJ32*AK$2)+(AL32*$AM$2)+(R32*$S$2) -> 6251.28 | BC32: =sum(F32:AM32) + sum(AP32:AY32) -> 441 | BD32: =0 -> 0 | BE32: =BC32 -> 441 | BF32: =iferror(BB32/BE32,"") -> 14.175238
A33: Wed | B33: =B32+1 -> 45686 | C33: 2 | D33: Week 1 | F33: 60 | H33: 60 | J33: 0 | L33: 0 | N33: 0 | P33: 0 | R33: 1 | T33: 160 | V33: 160 | X33: 0 | Z33: 0 | AB33: 0 | AD33: 0 | AF33: 0 | AH33: 0 | AJ33: 0 | AL33: 0 | AP33: 0 | AR33: 0 | AT33: 0 | AV33: 0 | AX33: 0 | AZ33: 0 | BB33: =(F33*G$2)+(H33*I$2)+(J33*K$2)+(L33*M$2)+(N33*O$2)+(P33*Q$2)+(T33*U$2)+(V33*W$2)+(X33*Y$2)+(Z33*AA$2)+(AB33*AC$2)+(AD33*AE$2)+(AP33*AQ$2)+(AR33*AS$2)+(AT33*AU$2)+(AV33*AW$2)+(AX33*AY$2)+(AF33*AG$2)+(AH33*AI$2)+(AJ33*AK$2)+(AL33*$AM$2)+(R33*$S$2) -> 6251.28 | BC33: =sum(F33:AM33) + sum(AP33:AY33) -> 441 | BD33: =0 -> 0 | BE33: =BC33 -> 441 | BF33: =iferror(BB33/BE33,"") -> 14.175238
A34: Thurs | B34: =B33+1 -> 45687 | C34: 2 | D34: Week 1 | F34: 60 | H34: 60 | J34: 0 | L34: 0 | N34: 0 | P34: 0 | R34: 1 | T34: 160 | V34: 160 | X34: 0 | Z34: 0 | AB34: 0 | AD34: 0 | AF34: 0 | AH34: 0 | AJ34: 0 | AL34: 0 | AP34: 0 | AR34: 0 | AT34: 0 | AV34: 0 | AX34: 0 | AZ34: 0 | BB34: =(F34*G$2)+(H34*I$2)+(J34*K$2)+(L34*M$2)+(N34*O$2)+(P34*Q$2)+(T34*U$2)+(V34*W$2)+(X34*Y$2)+(Z34*AA$2)+(AB34*AC$2)+(AD34*AE$2)+(AP34*AQ$2)+(AR34*AS$2)+(AT34*AU$2)+(AV34*AW$2)+(AX34*AY$2)+(AF34*AG$2)+(AH34*AI$2)+(AJ34*AK$2)+(AL34*$AM$2)+(R34*$S$2) -> 6251.28 | BC34: =sum(F34:AM34) + sum(AP34:AY34) -> 441 | BD34: =0 -> 0 | BE34: =BC34 -> 441 | BF34: =iferror(BB34/BE34,"") -> 14.175238
A35: Fri | B35: =B34+1 -> 45688 | C35: 2 | D35: Week 1 | F35: 60 | H35: 60 | J35: 0 | L35: 0 | N35: 0 | P35: 0 | R35: 1 | T35: 160 | V35: 160 | X35: 0 | Z35: 0 | AB35: 0 | AD35: 0 | AF35: 0 | AH35: 0 | AJ35: 0 | AL35: 0 | AP35: 0 | AR35: 0 | AT35: 0 | AV35: 0 | AX35: 0 | AZ35: 0 | BB35: =(F35*G$2)+(H35*I$2)+(J35*K$2)+(L35*M$2)+(N35*O$2)+(P35*Q$2)+(T35*U$2)+(V35*W$2)+(X35*Y$2)+(Z35*AA$2)+(AB35*AC$2)+(AD35*AE$2)+(AP35*AQ$2)+(AR35*AS$2)+(AT35*AU$2)+(AV35*AW$2)+(AX35*AY$2)+(AF35*AG$2)+(AH35*AI$2)+(AJ35*AK$2)+(AL35*$AM$2)+(R35*$S$2) -> 6251.28 | BC35: =sum(F35:AM35) + sum(AP35:AY35) -> 441 | BD35: =0 -> 0 | BE35: =BC35 -> 441 | BF35: =iferror(BB35/BE35,"") -> 14.175238
A36: Sat | B36: =B35+1 -> 45689 | C36: 2 | D36: Week 1 | F36: 60 | H36: 60 | J36: 0 | L36: 0 | N36: 0 | P36: 0 | R36: 0 | T36: 160 | V36: 160 | X36: 0 | Z36: 0 | AB36: 0 | AD36: 0 | AF36: 0 | AH36: 0 | AJ36: 0 | AL36: 0 | AP36: 0 | AR36: 0 | AT36: 0 | AV36: 0 | AX36: 0 | AZ36: 0 | BB36: =(F36*G$2)+(H36*I$2)+(J36*K$2)+(L36*M$2)+(N36*O$2)+(P36*Q$2)+(T36*U$2)+(V36*W$2)+(X36*Y$2)+(Z36*AA$2)+(AB36*AC$2)+(AD36*AE$2)+(AP36*AQ$2)+(AR36*AS$2)+(AT36*AU$2)+(AV36*AW$2)+(AX36*AY$2)+(AF36*AG$2)+(AH36*AI$2)+(AJ36*AK$2)+(AL36*$AM$2)+(R36*$S$2) -> 6228.4 | BC36: =sum(F36:AM36) + sum(AP36:AY36) -> 440 | BD36: =0 -> 0 | BE36: =BC36 -> 440 | BF36: =iferror(BB36/BE36,"") -> 14.155455
A37: Sun | B37: =B36+1 -> 45690 | C37: 2 | D37: Week 1 | F37: 0 | H37: 0 | J37: 0 | L37: 0 | N37: 0 | P37: 0 | T37: 0 | V37: 0 | X37: 0 | Z37: 0 | AB37: 0 | AD37: 0 | AF37: 0 | AH37: 0 | AJ37: 0 | AL37: 0 | AP37: 0 | AR37: 0 | AT37: 0 | AV37: 0 | AX37: 0 | AZ37: 0 | BB37: =(F37*G$2)+(H37*I$2)+(J37*K$2)+(L37*M$2)+(N37*O$2)+(P37*Q$2)+(T37*U$2)+(V37*W$2)+(X37*Y$2)+(Z37*AA$2)+(AB37*AC$2)+(AD37*AE$2)+(AP37*AQ$2)+(AR37*AS$2)+(AT37*AU$2)+(AV37*AW$2)+(AX37*AY$2)+(AF37*AG$2)+(AH37*AI$2)+(AJ37*AK$2)+(AL37*$AM$2)+(R37*$S$2) -> 0 | BC37: =sum(F37:AM37) + sum(AP37:AY37) -> 0 | BD37: =0 -> 0 | BE37: =BC37 -> 0 | BF37: =iferror(BB37/BE37,"")
A38: Mon | B38: =B37+1 -> 45691 | C38: 2 | D38: Week 2 | F38: 60 | H38: 60 | J38: 0 | L38: 0 | N38: 0 | P38: 0 | R38: 1 | T38: 170 | V38: 170 | X38: 155 | Z38: 0 | AB38: 0 | AD38: 0 | AF38: 0 | AH38: 0 | AJ38: 0 | AL38: 0 | AP38: 0 | AR38: 0 | AT38: 175 | AV38: 0 | AX38: 0 | AZ38: 0 | BB38: =(F38*G$2)+(H38*I$2)+(J38*K$2)+(L38*M$2)+(N38*O$2)+(P38*Q$2)+(T38*U$2)+(V38*W$2)+(X38*Y$2)+(Z38*AA$2)+(AB38*AC$2)+(AD38*AE$2)+(AP38*AQ$2)+(AR38*AS$2)+(AT38*AU$2)+(AV38*AW$2)+(AX38*AY$2)+(AF38*AG$2)+(AH38*AI$2)+(AJ38*AK$2)+(AL38*$AM$2)+(R38*$S$2) -> 8484.28 | BC38: =sum(F38:AM38) + sum(AP38:AY38) -> 791 | BD38: =0 -> 0 | BE38: =BC38 -> 791 | BF38: =iferror(BB38/BE38,"") -> 10.726018
A39: Tue | B39: =B38+1 -> 45692 | C39: 2 | D39: Week 2 | F39: 60 | H39: 60 | J39: 0 | L39: 0 | N39: 0 | P39: 0 | R39: 1 | T39: 170 | V39: 170 | X39: 0 | Z39: 0 | AB39: 0 | AD39: 0 | AF39: 0 | AH39: 0 | AJ39: 0 | AL39: 0 | AP39: 0 | AR39: 0 | AT39: 0 | AV39: 0 | AX39: 0 | AZ39: 0 | BB39: =(F39*G$2)+(H39*I$2)+(J39*K$2)+(L39*M$2)+(N39*O$2)+(P39*Q$2)+(T39*U$2)+(V39*W$2)+(X39*Y$2)+(Z39*AA$2)+(AB39*AC$2)+(AD39*AE$2)+(AP39*AQ$2)+(AR39*AS$2)+(AT39*AU$2)+(AV39*AW$2)+(AX39*AY$2)+(AF39*AG$2)+(AH39*AI$2)+(AJ39*AK$2)+(AL39*$AM$2)+(R39*$S$2) -> 6473.68 | BC39: =sum(F39:AM39) + sum(AP39:AY39) -> 461 | BD39: =0 -> 0 | BE39: =BC39 -> 461 | BF39: =iferror(BB39/BE39,"") -> 14.04269
A40: Wed | B40: =B39+1 -> 45693 | C40: 2 | D40: Week 2 | F40: 60 | H40: 60 | J40: 0 | L40: 0 | N40: 0 | P40: 0 | R40: 1 | T40: 170 | V40: 170 | X40: 0 | Z40: 0 | AB40: 0 | AD40: 0 | AF40: 0 | AH40: 0 | AJ40: 0 | AL40: 0 | AP40: 0 | AR40: 0 | AT40: 0 | AV40: 0 | AX40: 0 | AZ40: 0 | BB40: =(F40*G$2)+(H40*I$2)+(J40*K$2)+(L40*M$2)+(N40*O$2)+(P40*Q$2)+(T40*U$2)+(V40*W$2)+(X40*Y$2)+(Z40*AA$2)+(AB40*AC$2)+(AD40*AE$2)+(AP40*AQ$2)+(AR40*AS$2)+(AT40*AU$2)+(AV40*AW$2)+(AX40*AY$2)+(AF40*AG$2)+(AH40*AI$2)+(AJ40*AK$2)+(AL40*$AM$2)+(R40*$S$2) -> 6473.68 | BC40: =sum(F40:AM40) + sum(AP40:AY40) -> 461 | BD40: =0 -> 0 | BE40: =BC40 -> 461 | BF40: =iferror(BB40/BE40,"") -> 14.04269
A41: Thurs | B41: =B40+1 -> 45694 | C41: 2 | D41: Week 2 | F41: 60 | H41: 60 | J41: 0 | L41: 0 | N41: 0 | P41: 0 | R41: 1 | T41: 185 | V41: 185 | X41: 0 | Z41: 0 | AB41: 0 | AD41: 0 | AF41: 0 | AH41: 0 | AJ41: 0 | AL41: 0 | AP41: 0 | AR41: 0 | AT41: 0 | AV41: 0 | AX41: 0 | AZ41: 0 | BB41: =(F41*G$2)+(H41*I$2)+(J41*K$2)+(L41*M$2)+(N41*O$2)+(P41*Q$2)+(T41*U$2)+(V41*W$2)+(X41*Y$2)+(Z41*AA$2)+(AB41*AC$2)+(AD41*AE$2)+(AP41*AQ$2)+(AR41*AS$2)+(AT41*AU$2)+(AV41*AW$2)+(AX41*AY$2)+(AF41*AG$2)+(AH41*AI$2)+(AJ41*AK$2)+(AL41*$AM$2)+(R41*$S$2) -> 6807.28 | BC41: =sum(F41:AM41) + sum(AP41:AY41) -> 491 | BD41: =0 -> 0 | BE41: =BC41 -> 491 | BF41: =iferror(BB41/BE41,"") -> 13.864114
A42: Fri | B42: =B41+1 -> 45695 | C42: 2 | D42: Week 2 | F42: 60 | H42: 60 | J42: 0 | L42: 0 | N42: 0 | P42: 0 | R42: 1 | T42: 185 | V42: 185 | X42: 0 | Z42: 0 | AB42: 0 | AD42: 0 | AF42: 0 | AH42: 0 | AJ42: 0 | AL42: 0 | AP42: 0 | AR42: 0 | AT42: 0 | AV42: 0 | AX42: 0 | AZ42: 0 | BB42: =(F42*G$2)+(H42*I$2)+(J42*K$2)+(L42*M$2)+(N42*O$2)+(P42*Q$2)+(T42*U$2)+(V42*W$2)+(X42*Y$2)+(Z42*AA$2)+(AB42*AC$2)+(AD42*AE$2)+(AP42*AQ$2)+(AR42*AS$2)+(AT42*AU$2)+(AV42*AW$2)+(AX42*AY$2)+(AF42*AG$2)+(AH42*AI$2)+(AJ42*AK$2)+(AL42*$AM$2)+(R42*$S$2) -> 6807.28 | BC42: =sum(F42:AM42) + sum(AP42:AY42) -> 491 | BD42: =0 -> 0 | BE42: =BC42 -> 491 | BF42: =iferror(BB42/BE42,"") -> 13.864114
A43: Sat | B43: =B42+1 -> 45696 | C43: 2 | D43: Week 2 | F43: 60 | H43: 60 | J43: 0 | L43: 0 | N43: 0 | P43: 0 | R43: 4 | T43: 185 | V43: 185 | X43: 0 | Z43: 0 | AB43: 0 | AD43: 0 | AF43: 0 | AH43: 0 | AJ43: 0 | AL43: 0 | AP43: 0 | AR43: 0 | AT43: 0 | AV43: 0 | AX43: 0 | AZ43: 0 | BB43: =(F43*G$2)+(H43*I$2)+(J43*K$2)+(L43*M$2)+(N43*O$2)+(P43*Q$2)+(T43*U$2)+(V43*W$2)+(X43*Y$2)+(Z43*AA$2)+(AB43*AC$2)+(AD43*AE$2)+(AP43*AQ$2)+(AR43*AS$2)+(AT43*AU$2)+(AV43*AW$2)+(AX43*AY$2)+(AF43*AG$2)+(AH43*AI$2)+(AJ43*AK$2)+(AL43*$AM$2)+(R43*$S$2) -> 6875.92 | BC43: =sum(F43:AM43) + sum(AP43:AY43) -> 494 | BD43: =0 -> 0 | BE43: =BC43 -> 494 | BF43: =iferror(BB43/BE43,"") -> 13.918866
...

Sheet Clicker Counts - 2025
A1: Toronto Blue Jays @ Dunedin, FL | F1: Major League - PDC | R1: Minor League - PDC | AD1: Single A Jays | AJ1: SSM | AL1: Other | AX1: TOTALS
A2: Day | B2: Date | C2: Period | D2: Week | E2: Camp Name | F2: Breakfast | G2: 22.25 | H2: Lunch | I2: 22.25 | J2: Dinner | K2: 22.25 | L2: Umpire | M2: 22.25 | N2: Post Game Meal | O2: 22.25 | P2: Snack | Q2: 1.64 | R2: Breakfast | S2: 11.12 | T2: Lunch | U2: 11.12 | V2: Dinner | W2: 11.12 | X2: Blank | Y2: 0 | Z2: Blank | AA2: 0 | AB2: Blank | AC2: 0 | AD2: Breakfast | AE2: 15.89 | AF2: PRE-GAME | AG2: 15.89 | AH2: POST-GAME | AI2: 15.89 | AJ2: Stadium Staff Meals | AK2: 15.89 | AL2: Fun $$$$ Allocated | AM2: 27404 | AN2: Media Meals | AO2: 15 | AP2: MLB G&G - Pantry | AQ2: 1.64 | AR2: MiLB G&G - Pantry | AS2: 1.64 | AT2: MLB - Catering | AU2: 35 | AV2: Team Canada | AW2: 11.12 | AX2: Total Revenue | AY2: Total Meals | AZ2: Total Snacks | BA2: Total Charged Items | BB2: Average $/Item
A3: Mon | B3: 45656 | C3: 1 | D3: Week 1 | AX3: =(F3*G$2)+(H3*I$2)+(J3*K$2)+(L3*M$2)+(N3*O$2)+(P3*Q$2)+(R3*S$2)+(T3*U$2)+(V3*W$2)+(X3*Y$2)+(Z3*AA$2)+(AB3*AC$2)+(AN3*AO$2)+(AP3*AQ$2)+(AR3*AS$2)+(AT3*AU$2)+(AV3*AW$2)+(AD3*AE$2)+(AF3*AG$2)+(AH3*AI$2)+(AJ3*$AK$2) -> 0 | AY3: =sum(F3:AK3) + sum(AN3:AW3) -> 0 | AZ3: =0 -> 0 | BA3: =AY3 -> 0 | BB3: =iferror(AX3/BA3,"")
A4: Tue | B4: =B3+1 -> 45657 | C4: 1 | D4: Week 1 | AX4: =(F4*G$2)+(H4*I$2)+(J4*K$2)+(L4*M$2)+(N4*O$2)+(P4*Q$2)+(R4*S$2)+(T4*U$2)+(V4*W$2)+(X4*Y$2)+(Z4*AA$2)+(AB4*AC$2)+(AN4*AO$2)+(AP4*AQ$2)+(AR4*AS$2)+(AT4*AU$2)+(AV4*AW$2)+(AD4*AE$2)+(AF4*AG$2)+(AH4*AI$2)+(AJ4*$AK$2) -> 0 | AY4: =sum(F4:AK4) + sum(AN4:AW4) -> 0 | AZ4: =0 -> 0 | BA4: =AY4 -> 0 | BB4: =iferror(AX4/BA4,"")
A5: Wed | B5: =B4+1 -> 45658 | C5: 1 | D5: Week 1 | AX5: =(F5*G$2)+(H5*I$2)+(J5*K$2)+(L5*M$2)+(N5*O$2)+(P5*Q$2)+(R5*S$2)+(T5*U$2)+(V5*W$2)+(X5*Y$2)+(Z5*AA$2)+(AB5*AC$2)+(AN5*AO$2)+(AP5*AQ$2)+(AR5*AS$2)+(AT5*AU$2)+(AV5*AW$2)+(AD5*AE$2)+(AF5*AG$2)+(AH5*AI$2)+(AJ5*$AK$2) -> 0 | AY5: =sum(F5:AK5) + sum(AN5:AW5) -> 0 | AZ5: =0 -> 0 | BA5: =AY5 -> 0 | BB5: =iferror(AX5/BA5,"")
A6: Thurs | B6: =B5+1 -> 45659 | C6: 1 | D6: Week 1 | AX6: =(F6*G$2)+(H6*I$2)+(J6*K$2)+(L6*M$2)+(N6*O$2)+(P6*Q$2)+(R6*S$2)+(T6*U$2)+(V6*W$2)+(X6*Y$2)+(Z6*AA$2)+(AB6*AC$2)+(AN6*AO$2)+(AP6*AQ$2)+(AR6*AS$2)+(AT6*AU$2)+(AV6*AW$2)+(AD6*AE$2)+(AF6*AG$2)+(AH6*AI$2)+(AJ6*$AK$2) -> 0 | AY6: =sum(F6:AK6) + sum(AN6:AW6) -> 0 | AZ6: =0 -> 0 | BA6: =AY6 -> 0 | BB6: =iferror(AX6/BA6,"")
A7: Fri | B7: =B6+1 -> 45660 | C7: 1 | D7: Week 1 | AX7: =(F7*G$2)+(H7*I$2)+(J7*K$2)+(L7*M$2)+(N7*O$2)+(P7*Q$2)+(R7*S$2)+(T7*U$2)+(V7*W$2)+(X7*Y$2)+(Z7*AA$2)+(AB7*AC$2)+(AN7*AO$2)+(AP7*AQ$2)+(AR7*AS$2)+(AT7*AU$2)+(AV7*AW$2)+(AD7*AE$2)+(AF7*AG$2)+(AH7*AI$2)+(AJ7*$AK$2) -> 0 | AY7: =sum(F7:AK7) + sum(AN7:AW7) -> 0 | AZ7: =0 -> 0 | BA7: =AY7 -> 0 | BB7: =iferror(AX7/BA7,"")
A8: Sat | B8: =B7+1 -> 45661 | C8: 1 | D8: Week 1 | AX8: =(F8*G$2)+(H8*I$2)+(J8*K$2)+(L8*M$2)+(N8*O$2)+(P8*Q$2)+(R8*S$2)+(T8*U$2)+(V8*W$2)+(X8*Y$2)+(Z8*AA$2)+(AB8*AC$2)+(AN8*AO$2)+(AP8*AQ$2)+(AR8*AS$2)+(AT8*AU$2)+(AV8*AW$2)+(AD8*AE$2)+(AF8*AG$2)+(AH8*AI$2)+(AJ8*$AK$2) -> 0 | AY8: =sum(F8:AK8) + sum(AN8:AW8) -> 0 | AZ8: =0 -> 0 | BA8: =AY8 -> 0 | BB8: =iferror(AX8/BA8,"")
A9: Sun | B9: =B8+1 -> 45662 | C9: 1 | D9: Week 1 | AX9: =(F9*G$2)+(H9*I$2)+(J9*K$2)+(L9*M$2)+(N9*O$2)+(P9*Q$2)+(R9*S$2)+(T9*U$2)+(V9*W$2)+(X9*Y$2)+(Z9*AA$2)+(AB9*AC$2)+(AN9*AO$2)+(AP9*AQ$2)+(AR9*AS$2)+(AT9*AU$2)+(AV9*AW$2)+(AD9*AE$2)+(AF9*AG$2)+(AH9*AI$2)+(AJ9*$AK$2) -> 0 | AY9: =sum(F9:AK9) + sum(AN9:AW9) -> 0 | AZ9: =0 -> 0 | BA9: =AY9 -> 0 | BB9: =iferror(AX9/BA9,"")
A10: Mon | B10: =B9+1 -> 45663 | C10: 1 | D10: Week 2 | R10: 65 | T10: 73 | AX10: =(F10*G$2)+(H10*I$2)+(J10*K$2)+(L10*M$2)+(N10*O$2)+(P10*Q$2)+(R10*S$2)+(T10*U$2)+(V10*W$2)+(X10*Y$2)+(Z10*AA$2)+(AB10*AC$2)+(AN10*AO$2)+(AP10*AQ$2)+(AR10*AS$2)+(AT10*AU$2)+(AV10*AW$2)+(AD10*AE$2)+(AF10*AG$2)+(AH10*AI$2)+(AJ10*$AK$2) -> 1534.56 | AY10: =sum(F10:AK10) + sum(AN10:AW10) -> 138 | AZ10: =0 -> 0 | BA10: =AY10 -> 138 | BB10: =iferror(AX10/BA10,"") -> 11.12
A11: Tue | B11: =B10+1 -> 45664 | C11: 1 | D11: Week 2 | R11: 79 | T11: 89 | AX11: =(F11*G$2)+(H11*I$2)+(J11*K$2)+(L11*M$2)+(N11*O$2)+(P11*Q$2)+(R11*S$2)+(T11*U$2)+(V11*W$2)+(X11*Y$2)+(Z11*AA$2)+(AB11*AC$2)+(AN11*AO$2)+(AP11*AQ$2)+(AR11*AS$2)+(AT11*AU$2)+(AV11*AW$2)+(AD11*AE$2)+(AF11*AG$2)+(AH11*AI$2)+(AJ11*$AK$2) -> 1868.16 | AY11: =sum(F11:AK11) + sum(AN11:AW11) -> 168 | AZ11: =0 -> 0 | BA11: =AY11 -> 168 | BB11: =iferror(AX11/BA11,"") -> 11.12
A12: Wed | B12: =B11+1 -> 45665 | C12: 1 | D12: Week 2 | R12: 83 | T12: 88 | AX12: =(F12*G$2)+(H12*I$2)+(J12*K$2)+(L12*M$2)+(N12*O$2)+(P12*Q$2)+(R12*S$2)+(T12*U$2)+(V12*W$2)+(X12*Y$2)+(Z12*AA$2)+(AB12*AC$2)+(AN12*AO$2)+(AP12*AQ$2)+(AR12*AS$2)+(AT12*AU$2)+(AV12*AW$2)+(AD12*AE$2)+(AF12*AG$2)+(AH12*AI$2)+(AJ12*$AK$2) -> 1901.52 | AY12: =sum(F12:AK12) + sum(AN12:AW12) -> 171 | AZ12: =0 -> 0 | BA12: =AY12 -> 171 | BB12: =iferror(AX12/BA12,"") -> 11.12
A13: Thurs | B13: =B12+1 -> 45666 | C13: 1 | D13: Week 2 | R13: 72 | T13: 96 | AX13: =(F13*G$2)+(H13*I$2)+(J13*K$2)+(L13*M$2)+(N13*O$2)+(P13*Q$2)+(R13*S$2)+(T13*U$2)+(V13*W$2)+(X13*Y$2)+(Z13*AA$2)+(AB13*AC$2)+(AN13*AO$2)+(AP13*AQ$2)+(AR13*AS$2)+(AT13*AU$2)+(AV13*AW$2)+(AD13*AE$2)+(AF13*AG$2)+(AH13*AI$2)+(AJ13*$AK$2) -> 1868.16 | AY13: =sum(F13:AK13) + sum(AN13:AW13) -> 168 | AZ13: =0 -> 0 | BA13: =AY13 -> 168 | BB13: =iferror(AX13/BA13,"") -> 11.12
A14: Fri | B14: =B13+1 -> 45667 | C14: 1 | D14: Week 2 | R14: 87 | T14: 86 | AX14: =(F14*G$2)+(H14*I$2)+(J14*K$2)+(L14*M$2)+(N14*O$2)+(P14*Q$2)+(R14*S$2)+(T14*U$2)+(V14*W$2)+(X14*Y$2)+(Z14*AA$2)+(AB14*AC$2)+(AN14*AO$2)+(AP14*AQ$2)+(AR14*AS$2)+(AT14*AU$2)+(AV14*AW$2)+(AD14*AE$2)+(AF14*AG$2)+(AH14*AI$2)+(AJ14*$AK$2) -> 1923.76 | AY14: =sum(F14:AK14) + sum(AN14:AW14) -> 173 | AZ14: =0 -> 0 | BA14: =AY14 -> 173 | BB14: =iferror(AX14/BA14,"") -> 11.12
A15: Sat | B15: =B14+1 -> 45668 | C15: 1 | D15: Week 2 | R15: 0 | T15: 0 | AX15: =(F15*G$2)+(H15*I$2)+(J15*K$2)+(L15*M$2)+(N15*O$2)+(P15*Q$2)+(R15*S$2)+(T15*U$2)+(V15*W$2)+(X15*Y$2)+(Z15*AA$2)+(AB15*AC$2)+(AN15*AO$2)+(AP15*AQ$2)+(AR15*AS$2)+(AT15*AU$2)+(AV15*AW$2)+(AD15*AE$2)+(AF15*AG$2)+(AH15*AI$2)+(AJ15*$AK$2) -> 0 | AY15: =sum(F15:AK15) + sum(AN15:AW15) -> 0 | AZ15: =0 -> 0 | BA15: =AY15 -> 0 | BB15: =iferror(AX15/BA15,"")
A16: Sun | B16: =B15+1 -> 45669 | C16: 1 | D16: Week 2 | R16: 0 | T16: 0 | AX16: =(F16*G$2)+(H16*I$2)+(J16*K$2)+(L16*M$2)+(N16*O$2)+(P16*Q$2)+(R16*S$2)+(T16*U$2)+(V16*W$2)+(X16*Y$2)+(Z16*AA$2)+(AB16*AC$2)+(AN16*AO$2)+(AP16*AQ$2)+(AR16*AS$2)+(AT16*AU$2)+(AV16*AW$2)+(AD16*AE$2)+(AF16*AG$2)+(AH16*AI$2)+(AJ16*$AK$2) -> 0 | AY16: =sum(F16:AK16) + sum(AN16:AW16) -> 0 | AZ16: =0 -> 0 | BA16: =AY16 -> 0 | BB16: =iferror(AX16/BA16,"")
A17: Mon | B17: =B16+1 -> 45670 | C17: 1 | D17: Week 3 | F17: 4 | H17: 9 | R17: 100 | T17: 91 | AX17: =(F17*G$2)+(H17*I$2)+(J17*K$2)+(L17*M$2)+(N17*O$2)+(P17*Q$2)+(R17*S$2)+(T17*U$2)+(V17*W$2)+(X17*Y$2)+(Z17*AA$2)+(AB17*AC$2)+(AN17*AO$2)+(AP17*AQ$2)+(AR17*AS$2)+(AT17*AU$2)+(AV17*AW$2)+(AD17*AE$2)+(AF17*AG$2)+(AH17*AI$2)+(AJ17*$AK$2) -> 2413.17 | AY17: =sum(F17:AK17) + sum(AN17:AW17) -> 204 | AZ17: =0 -> 0 | BA17: =AY17 -> 204 | BB17: =iferror(AX17/BA17,"") -> 11.829265
A18: Tue | B18: =B17+1 -> 45671 | C18: 1 | D18: Week 3 | F18: 6 | H18: 9 | R18: 93 | T18: 96 | AX18: =(F18*G$2)+(H18*I$2)+(J18*K$2)+(L18*M$2)+(N18*O$2)+(P18*Q$2)+(R18*S$2)+(T18*U$2)+(V18*W$2)+(X18*Y$2)+(Z18*AA$2)+(AB18*AC$2)+(AN18*AO$2)+(AP18*AQ$2)+(AR18*AS$2)+(AT18*AU$2)+(AV18*AW$2)+(AD18*AE$2)+(AF18*AG$2)+(AH18*AI$2)+(AJ18*$AK$2) -> 2435.43 | AY18: =sum(F18:AK18) + sum(AN18:AW18) -> 204 | AZ18: =0 -> 0 | BA18: =AY18 -> 204 | BB18: =iferror(AX18/BA18,"") -> 11.938382
A19: Wed | B19: =B18+1 -> 45672 | C19: 1 | D19: Week 3 | F19: 12 | H19: 12 | R19: 76 | T19: 103 | AX19: =(F19*G$2)+(H19*I$2)+(J19*K$2)+(L19*M$2)+(N19*O$2)+(P19*Q$2)+(R19*S$2)+(T19*U$2)+(V19*W$2)+(X19*Y$2)+(Z19*AA$2)+(AB19*AC$2)+(AN19*AO$2)+(AP19*AQ$2)+(AR19*AS$2)+(AT19*AU$2)+(AV19*AW$2)+(AD19*AE$2)+(AF19*AG$2)+(AH19*AI$2)+(AJ19*$AK$2) -> 2524.48 | AY19: =sum(F19:AK19) + sum(AN19:AW19) -> 203 | AZ19: =0 -> 0 | BA19: =AY19 -> 203 | BB19: =iferror(AX19/BA19,"") -> 12.435862
A20: Thurs | B20: =B19+1 -> 45673 | C20: 1 | D20: Week 3 | F20: 10 | H20: 13 | R20: 93 | T20: 92 | AX20: =(F20*G$2)+(H20*I$2)+(J20*K$2)+(L20*M$2)+(N20*O$2)+(P20*Q$2)+(R20*S$2)+(T20*U$2)+(V20*W$2)+(X20*Y$2)+(Z20*AA$2)+(AB20*AC$2)+(AN20*AO$2)+(AP20*AQ$2)+(AR20*AS$2)+(AT20*AU$2)+(AV20*AW$2)+(AD20*AE$2)+(AF20*AG$2)+(AH20*AI$2)+(AJ20*$AK$2) -> 2568.95 | AY20: =sum(F20:AK20) + sum(AN20:AW20) -> 208 | AZ20: =0 -> 0 | BA20: =AY20 -> 208 | BB20: =iferror(AX20/BA20,"") -> 12.350721
A21: Fri | B21: =B20+1 -> 45674 | C21: 1 | D21: Week 3 | F21: 10 | H21: 13 | R21: 102 | T21: 106 | AX21: =(F21*G$2)+(H21*I$2)+(J21*K$2)+(L21*M$2)+(N21*O$2)+(P21*Q$2)+(R21*S$2)+(T21*U$2)+(V21*W$2)+(X21*Y$2)+(Z21*AA$2)+(AB21*AC$2)+(AN21*AO$2)+(AP21*AQ$2)+(AR21*AS$2)+(AT21*AU$2)+(AV21*AW$2)+(AD21*AE$2)+(AF21*AG$2)+(AH21*AI$2)+(AJ21*$AK$2) -> 2824.71 | AY21: =sum(F21:AK21) + sum(AN21:AW21) -> 231 | AZ21: =0 -> 0 | BA21: =AY21 -> 231 | BB21: =iferror(AX21/BA21,"") -> 12.228182
A22: Sat | B22: =B21+1 -> 45675 | C22: 1 | D22: Week 3 | AX22: =(F22*G$2)+(H22*I$2)+(J22*K$2)+(L22*M$2)+(N22*O$2)+(P22*Q$2)+(R22*S$2)+(T22*U$2)+(V22*W$2)+(X22*Y$2)+(Z22*AA$2)+(AB22*AC$2)+(AN22*AO$2)+(AP22*AQ$2)+(AR22*AS$2)+(AT22*AU$2)+(AV22*AW$2)+(AD22*AE$2)+(AF22*AG$2)+(AH22*AI$2)+(AJ22*$AK$2) -> 0 | AY22: =sum(F22:AK22) + sum(AN22:AW22) -> 0 | AZ22: =0 -> 0 | BA22: =AY22 -> 0 | BB22: =iferror(AX22/BA22,"")
A23: Sun | B23: =B22+1 -> 45676 | C23: 1 | D23: Week 3 | AX23: =(F23*G$2)+(H23*I$2)+(J23*K$2)+(L23*M$2)+(N23*O$2)+(P23*Q$2)+(R23*S$2)+(T23*U$2)+(V23*W$2)+(X23*Y$2)+(Z23*AA$2)+(AB23*AC$2)+(AN23*AO$2)+(AP23*AQ$2)+(AR23*AS$2)+(AT23*AU$2)+(AV23*AW$2)+(AD23*AE$2)+(AF23*AG$2)+(AH23*AI$2)+(AJ23*$AK$2) -> 0 | AY23: =sum(F23:AK23) + sum(AN23:AW23) -> 0 | AZ23: =0 -> 0 | BA23: =AY23 -> 0 | BB23: =iferror(AX23/BA23,"")
A24: Mon | B24: =B23+1 -> 45677 | C24: 1 | D24: Week 4 | F24: 7 | H24: 16 | R24: 135 | T24: 142 | AX24: =(F24*G$2)+(H24*I$2)+(J24*K$2)+(L24*M$2)+(N24*O$2)+(P24*Q$2)+(R24*S$2)+(T24*U$2)+(V24*W$2)+(X24*Y$2)+(Z24*AA$2)+(AB24*AC$2)+(AN24*AO$2)+(AP24*AQ$2)+(AR24*AS$2)+(AT24*AU$2)+(AV24*AW$2)+(AD24*AE$2)+(AF24*AG$2)+(AH24*AI$2)+(AJ24*$AK$2) -> 3591.99 | AY24: =sum(F24:AK24) + sum(AN24:AW24) -> 300 | AZ24: =0 -> 0 | BA24: =AY24 -> 300 | BB24: =iferror(AX24/BA24,"") -> 11.9733
A25: Tue | B25: =B24+1 -> 45678 | C25: 1 | D25: Week 4 | F25: 21 | H25: 29 | R25: 143 | T25: 167 | AX25: =(F25*G$2)+(H25*I$2)+(J25*K$2)+(L25*M$2)+(N25*O$2)+(P25*Q$2)+(R25*S$2)+(T25*U$2)+(V25*W$2)+(X25*Y$2)+(Z25*AA$2)+(AB25*AC$2)+(AN25*AO$2)+(AP25*AQ$2)+(AR25*AS$2)+(AT25*AU$2)+(AV25*AW$2)+(AD25*AE$2)+(AF25*AG$2)+(AH25*AI$2)+(AJ25*$AK$2) -> 4559.7 | AY25: =sum(F25:AK25) + sum(AN25:AW25) -> 360 | AZ25: =0 -> 0 | BA25: =AY25 -> 360 | BB25: =iferror(AX25/BA25,"") -> 12.665833
A26: Wed | B26: =B25+1 -> 45679 | C26: 1 | D26: Week 4 | F26: 16 | H26: 19 | R26: 175 | T26: 207 | AX26: =(F26*G$2)+(H26*I$2)+(J26*K$2)+(L26*M$2)+(N26*O$2)+(P26*Q$2)+(R26*S$2)+(T26*U$2)+(V26*W$2)+(X26*Y$2)+(Z26*AA$2)+(AB26*AC$2)+(AN26*AO$2)+(AP26*AQ$2)+(AR26*AS$2)+(AT26*AU$2)+(AV26*AW$2)+(AD26*AE$2)+(AF26*AG$2)+(AH26*AI$2)+(AJ26*$AK$2) -> 5026.59 | AY26: =sum(F26:AK26) + sum(AN26:AW26) -> 417 | AZ26: =0 -> 0 | BA26: =AY26 -> 417 | BB26: =iferror(AX26/BA26,"") -> 12.054173
A27: Thurs | B27: =B26+1 -> 45680 | C27: 1 | D27: Week 4 | F27: 20 | H27: 20 | R27: 148 | T27: 202 | AX27: =(F27*G$2)+(H27*I$2)+(J27*K$2)+(L27*M$2)+(N27*O$2)+(P27*Q$2)+(R27*S$2)+(T27*U$2)+(V27*W$2)+(X27*Y$2)+(Z27*AA$2)+(AB27*AC$2)+(AN27*AO$2)+(AP27*AQ$2)+(AR27*AS$2)+(AT27*AU$2)+(AV27*AW$2)+(AD27*AE$2)+(AF27*AG$2)+(AH27*AI$2)+(AJ27*$AK$2) -> 4782 | AY27: =sum(F27:AK27) + sum(AN27:AW27) -> 390 | AZ27: =0 -> 0 | BA27: =AY27 -> 390 | BB27: =iferror(AX27/BA27,"") -> 12.261538
A28: Fri | B28: =B27+1 -> 45681 | C28: 1 | D28: Week 4 | F28: 17 | H28: 21 | R28: 156 | T28: 164 | AX28: =(F28*G$2)+(H28*I$2)+(J28*K$2)+(L28*M$2)+(N28*O$2)+(P28*Q$2)+(R28*S$2)+(T28*U$2)+(V28*W$2)+(X28*Y$2)+(Z28*AA$2)+(AB28*AC$2)+(AN28*AO$2)+(AP28*AQ$2)+(AR28*AS$2)+(AT28*AU$2)+(AV28*AW$2)+(AD28*AE$2)+(AF28*AG$2)+(AH28*AI$2)+(AJ28*$AK$2) -> 4403.9 | AY28: =sum(F28:AK28) + sum(AN28:AW28) -> 358 | AZ28: =0 -> 0 | BA28: =AY28 -> 358 | BB28: =iferror(AX28/BA28,"") -> 12.301397
